Workbook
Name Actual: (Base_Plan!PeriodInActual*(Base_Plan!#REF!>0))*Base_Plan!PeriodInPlan
Name Actual: (PeriodInActual*(Actual_Plan!$F1>0))*PeriodInPlan
Name ActualBeyond: Base_Plan!PeriodInActual*(Base_Plan!#REF!>0)
Name ActualBeyond: PeriodInActual*(Actual_Plan!$F1>0)
Name PercentComplete: Base_Plan!PercentCompleteBeyond*Base_Plan!PeriodInPlan
Name PercentComplete: PercentCompleteBeyond*PeriodInPlan
Name period_selected: Base_Plan!$P$1
Name period_selected: Actual_Plan!$P$3
Name PeriodInActual: Base_Plan!A$5=MEDIAN(Base_Plan!A$5,Base_Plan!#REF!,Base_Plan!#REF!+Base_Plan!#REF!-1)
Name PeriodInActual: Actual_Plan!A$8=MEDIAN(Actual_Plan!A$8,Actual_Plan!$F1,Actual_Plan!$F1+Actual_Plan!$G1-1)
Name PeriodInPlan: Base_Plan!A$5=MEDIAN(Base_Plan!A$5,Base_Plan!$D1,Base_Plan!$D1+Base_Plan!$E1-1)
Name PeriodInPlan: Actual_Plan!A$8=MEDIAN(Actual_Plan!A$8,Actual_Plan!$D1,Actual_Plan!$D1+Actual_Plan!$E1-1)
Name Plan: Base_Plan!PeriodInPlan*(Base_Plan!$D1>0)
Name Plan: PeriodInPlan*(Actual_Plan!$D1>0)

Sheet Checklist
A1: Nature | B1: # | C1: Field | D1: Description | G1: Sell Value | H1: Effort | I1: Timesheet | J1: OTS (Snapshot) | K1: Allocations
A2: Type | B2: 1 | C2: OTS (Snapshot) or Type | D2: As project is T&M or CMS please confirm why the recognition is not 100%
A3: Type | B3: =+B2+1 -> 2 | C3: Effort or Timesheet or OTS (Snapshot) | D3: As project is T&M please confirm why there's deviation in the project
A4: R. End | B4: =+B3+1 -> 3 | C4: Allocations or Estimate End date | D4: Estimated End Date is not coherent with allocations
A5: Type | B5: =+B4+1 -> 4 | C5: Sell Value or Allocations | D5: As project is T&M or CMS please put value in the timesheet and in the allocations
A6: Value | B6: =+B5+1 -> 5 | C6: Sell Value | D6: New value: confirm estimation and agreement was sent to financial department
A7: Value | B7: =+B6+1 -> 6 | C7: Sell Value | D7: New Value higher than 30% of the total previous amount of project: create new project?
A8: Effort | B8: =+B7+1 -> 7 | C8: Sell Value or Effort | D8: Sell value without Effort or Effort without sell value
A9: Dev | B9: =+B8+1 -> 8 | C9: Dev | D9: Dev is too high

Sheet List
A1: Dates | B1: Select Report Month | C1: Return | H1: Denominação Original | I1: Empresa | J1: RC1 | K1: RC2 | L1: Currency | M1: Taxes | N1: Language | O1: Due Date
A2: 45658 | B2: =+PT!A4 -> 2025-9 | C2: 1 | E2: PT | F2: KSR,S.A. | H2: AHOLD US | I2: AHOLD US | J2: RC US | L2: USD | M2: 0 | N2: 4 | O2: 30 | P2: 1 | Q2: Janeiro | R2: Enero | S2: January | U2: Y | V2: Time and Material | W2: T&M | X2: TO BE STARTED | Y2: Very high | Z2: 0 | AA2: I | AC2: MATRIX of Probability and Impact
A3: 45659 | B3: =+PT!A5 -> 2025-10 | C3: =+C2+1 -> 2 | E3: MX | F3: RETAILKSR SA de CV | H3: Retail Equation INC, US | I3: Appriss Retail | J3: RC PT | L3: USD | M3: 0 | N3: 4 | O3: 30 | P3: =+P2+1 -> 2 | Q3: Fevereiro | R3: Febrero | S3: February | U3: N | V3: Fixed Price | W3: FP | X3: IN PROGRESS | Y3: High | Z3: 0.25 | AA3: R | AC3: PROBABILITY
A4: 45660 | B4: =+PT!A6 -> 2025-11 | C4: =+C3+1 -> 3 | E4: CL | F4: Retail Consult KSR SpA | H4: Bata Chile | I4: BATA | J4: RC CL | K4: RC PT | M4: 0 | N4: 3 | O4: 30 | P4: =+P3+1 -> 3 | Q4: Março | R4: Marzo | S4: March | V4: CMS | W4: CMS | X4: COMPLETED | Y4: Medium | Z4: 0.5 | AC4: Very high | AD4: 25 | AE4: 20 | AF4: 15 | AG4: 10 | AH4: 5 | AI4: Effort | AJ4: Red | AK4: RED | AL4: RED | AM4: RED
A5: 45661 | B5: =+PT!A7 -> 2025-12 | C5: =+C4+1 -> 4 | E5: MT | F5: Retail Consult KSR Limited | H5: Empresas Comerciales S.A. | I5: BATA | J5: RC CL | K5: RC PT | M5: 0 | N5: 3 | O5: 30 | P5: =+P4+1 -> 4 | Q5: Abril | R5: Abril | S5: April | X5: LATE | Y5: Low | Z5: 0.75 | AC5: High | AD5: 20 | AE5: 16 | AF5: 12 | AG5: 8 | AH5: 4 | AJ5: Amber | AK5: RED | AL5: AMBER | AM5: GREEN
A6: 45662 | B6: =+PT!A8 -> 2026-1 | C6: =+C5+1 -> 5 | E6: DE | F6: Retail-Consult KSR GmbH | H6: COMPAR | I6: COMPAR | J6: RC PT | L6: EUR | M6: 0 | N6: 4 | O6: 30 | P6: =+P5+1 -> 5 | Q6: Maio | R6: Mayo | S6: May | X6: CANCELLED | Y6: Very Low | Z6: 1 | AC6: Medium | AD6: 15 | AE6: 12 | AF6: 9 | AG6: 12 | AH6: 3 | AJ6: Green | AK6: RED | AL6: GREEN | AM6: GREEN
A7: 45663 | B7: =+PT!A9 -> 2026-2 | C7: =+C6+1 -> 6 | E7: BR | F7: Retail Consult KSR - Soluções para Varejo Ltda | H7: ABASIC, S.L. | I7: DESIGUAL | J7: RC PT | L7: EUR | M7: 0 | N7: 3 | O7: 30 | P7: =+P6+1 -> 6 | Q7: Junho | R7: Junio | S7: June | X7: STAND BY | AC7: Low | AD7: 10 | AE7: 8 | AF7: 6 | AG7: 4 | AH7: 2 | AK7: Red | AL7: Amber | AM7: Green
A8: 45664 | B8: =+PT!A10 -> 2026-3 | C8: =+C7+1 -> 7 | E8: US | F8: Retail Consult LLC | H8: Ericsson | I8: Ericsson | J8: RC PT | L8: USD | M8: 0 | N8: 3 | O8: 90 | P8: =+P7+1 -> 7 | Q8: Julho | R8: Julio | S8: July | AC8: Very Low | AD8: 5 | AE8: 4 | AF8: 3 | AG8: 2 | AH8: 1 | AJ8: Time
A9: 45665 | B9: =+PT!A11 -> 2026-4 | C9: =+C8+1 -> 8 | E9: CN | F9: Retail Consult CN | H9: ERICSSON CHILE S.A. | I9: Ericsson | J9: RC PT | L9: USD | M9: 0 | N9: 3 | O9: 90 | P9: =+P8+1 -> 8 | Q9: Agosto | R9: Agosto | S9: August | AC9: IMPACT | AD9: Very high | AE9: High | AF9: Medium | AG9: Low | AH9: Very Low
A10: 45666 | B10: =+PT!A12 -> 2026-5 | C10: =+C9+1 -> 9 | H10: Farmácias del ahorro | I10: Farmácias del ahorro | J10: RC MX | M10: 0 | N10: 3 | O10: 30 | P10: =+P9+1 -> 9 | Q10: Setembro | R10: Septiembre | S10: September
A11: 45667 | B11: =+PT!A13 -> 2026-6 | C11: =+C10+1 -> 10 | H11: FARMATODO | I11: FARMATODO | J11: RC PT | K11: RC MT | L11: USD | M11: 0 | N11: 3 | O11: 30 | P11: =+P10+1 -> 10 | Q11: Outubro | R11: Octubre | S11: October
A12: 45668 | B12: =+PT!A14 -> 2026-7 | C12: =+C11+1 -> 11 | H12: FARMATODO, C.A. | I12: FARMATODO | J12: RC PT | K12: RC MT | L12: USD | M12: 0 | N12: 3 | O12: 30 | P12: =+P11+1 -> 11 | Q12: Novembro | R12: Noviembre | S12: November | X12: Scope | AJ12: Red
A13: 45669 | B13: =+PT!A15 -> 2026-8 | C13: =+C12+1 -> 12 | H13: Difarma | I13: FCV | J13: RC CL | M13: 0 | N13: 3 | O13: 30 | P13: =+P12+1 -> 12 | Q13: Dezembro | R13: Diciembre | S13: December | X13: Plan | AJ13: Amber
A14: 45670 | B14: =+PT!A16 -> 2026-9 | C14: =+C13+1 -> 13 | H14: FYBECA | I14: FYBECA | J14: RC DE | M14: 0 | N14: 3 | O14: 30 | X14: Financial | AJ14: Green
A15: 45671 | B15: =+PT!A17 -> 2026-10 | C15: =+C14+1 -> 14 | H15: Garcia | I15: Garcia | J15: RC MX | M15: 0 | N15: 3 | O15: 30 | X15: Scope & Plan
A16: 45672 | B16: =+PT!A18 -> 2026-11 | C16: =+C15+1 -> 15 | H16: HugoBoss | I16: HugoBoss | J16: RC DE | M16: 0 | N16: 4 | O16: 30 | X16: Scope & Financial
A17: 45673 | B17: =+PT!A19 -> 2026-12 | C17: =+C16+1 -> 16 | H17: Lowes | I17: Lowes | J17: RC MX | K17: RC US | M17: 0 | N17: 3 | O17: 30 | X17: Plan & Financial
A18: 45674 | B18: =+PT!A20 -> 2027-1 | C18: =+C17+1 -> 17 | H18: Makro | I18: Makro | J18: RC BR | M18: 0 | N18: 2 | O18: 30
A19: 45675 | B19: =+PT!A21 -> 2027-2 | C19: =+C18+1 -> 18 | H19: Marti | I19: Marti | J19: RC MX | M19: 0 | N19: 3 | O19: 30
A20: 45676 | B20: =+PT!A22 -> 2027-3 | C20: =+C19+1 -> 19 | H20: Mega Santamaria | I20: Mega Santamaria | J20: RC DE | M20: 0 | N20: 3 | O20: 30
A21: 45677 | B21: =+PT!A23 -> 2027-4 | C21: =+C20+1 -> 20 | H21: OFFICE DEPOT | I21: OFFICE DEPOT | J21: RC MX | L21: USD | M21: 0 | N21: 4 | O21: 30
A22: 45678 | B22: =+PT!A24 -> 2027-5 | C22: =+C21+1 -> 21 | H22: ORACLE | I22: ORACLE | J22: RC PT | L22: USD | M22: 0 | N22: 4 | O22: 45
A23: 45679 | B23: =+PT!A25 -> 2027-6 | C23: =+C22+1 -> 22 | H23: Oracle Corporation UK Limited | I23: ORACLE | J23: RC PT | L23: EUR | M23: 0 | N23: 4 | O23: 45
A24: 45680 | B24: =+PT!A26 -> 2027-7 | C24: =+C23+1 -> 23 | H24: Oracle France, S.A.S | I24: ORACLE | J24: RC PT | L24: EUR | M24: 0 | N24: 4 | O24: 45
A25: 45681 | B25: =+PT!A27 -> 2027-8 | C25: =+C24+1 -> 24 | H25: OXXO | I25: OXXO | J25: RC MX | M25: 0 | N25: 3 | O25: 30
A26: 45682 | B26: =+PT!A28 -> 2027-9 | C26: =+C25+1 -> 25 | H26: BARHOLD, S.A. | I26: PARFOIS | J26: RC PT | L26: EUR | M26: 0.23 | N26: 2 | O26: 30
A27: 45683 | B27: =+PT!A29 -> - | C27: =+C26+1 -> 26 | H27: PARFOIS | I27: PARFOIS | J27: RC PT | L27: EUR | M27: 0.23 | N27: 2 | O27: 30
A28: 45684 | B28: =+PT!A30 -> - | C28: =+C27+1 -> 27 | H28: Retail Consult KSR Limited | I28: Retail Consult KSR Limited | M28: 0 | N28: 4 | O28: 30
A29: 45685 | B29: =+PT!A31 -> - | C29: =+C28+1 -> 28 | H29: RETAILKSR SA DE CV | I29: RETAILKSR SA de CV | M29: 0 | N29: 3 | O29: 30
A30: 45686 | B30: =+PT!A32 -> - | C30: =+C29+1 -> 29 | H30: SONAE CENTER SERVIÇOS II S.A. | I30: SONAE | J30: RC PT | L30: EUR | M30: 0.23 | N30: 2 | O30: 30
A31: 45687 | B31: =+PT!A33 -> - | C31: =+C30+1 -> 30 | H31: Tata Tia | I31: Tata Tia | J31: RC DE | M31: 0 | N31: 4 | O31: 30
A32: 45688 | B32: =+PT!A34 -> - | C32: =+C31+1 -> 31 | H32: SONAE | I32: SONAE | J32: RC PT | L32: EUR | M32: 0.23 | N32: 2 | O32: 30
A33: 45689 | B33: =+PT!A35 -> - | C33: =+C32+1 -> 32 | H33: Desigual | I33: DESIGUAL | J33: RC PT | L33: EUR | M33: 0 | N33: 3 | O33: 30
A34: 45690 | B34: =+PT!A36 -> - | C34: =+C33+1 -> 33 | H34: Appriss Retail | I34: Appriss Retail | J34: RC PT | L34: USD | M34: 0 | N34: 4 | O34: 30
A35: 45691 | B35: =+PT!A37 -> - | C35: =+C34+1 -> 34 | H35: FARMAHORRO | I35: FARMAHORRO | J35: RC MT | M35: 0 | N35: 3 | O35: 30
A36: 45692 | B36: =+PT!A38 -> - | C36: =+C35+1 -> 35 | H36: KSR, S.A. | I36: KSR, S.A. | M36: 0 | N36: 2 | O36: 30
A37: 45693 | B37: =+PT!A39 -> - | C37: =+C36+1 -> 36 | H37: Retail Consult LLC | I37: Retail Consult LLC | M37: 0 | N37: 4 | O37: 30
A38: 45694 | B38: =+PT!A40 -> - | C38: =+C37+1 -> 37 | H38: Retail Consult KSR GmbH | I38: Retail Consult KSR GmbH | M38: 0 | N38: 4 | O38: 30
A39: 45695 | B39: =+PT!A41 -> - | C39: =+C38+1 -> 38 | H39: Manufactura Boliviana | I39: BATA | J39: RC CL | M39: 0.125 | N39: 3 | O39: 30
A40: 45696 | B40: =+PT!A42 -> - | C40: =+C39+1 -> 39 | H40: Calzacuero CA | I40: BATA | J40: RC CL | M40: 0.25 | N40: 3 | O40: 30
...

Sheet Summary
A1: Version: V3
B2: Month Delivery Report - Summary
B4: Code | D4: RC06067 | H4: Operational Manager | J4: Henrique Pereira Alves | N4: Contract Start Date | P4: 45929
B5: Name | D5: ARROCHA (MX) CMS 2025 | H5: Account Manager | J5: Javier Albez | N5: Contract End Date | P5: 46657 | R5: =IF(YEAR(P5)-LEFT(P7,4)=0,IF(LEN(P7)=6,IF(MONTH(P5)-RIGHT(P7)-3<0,"Contract is about to expire !",IF(LEN(P7)=7,IF(MONTH(P5)-RIGHT(P7,2)-3<0,"Contract is about to expire !"),""))),"")
B6: Account | D6: ARROCHA | H6: Service Manager | J6: Luiz Felipe Horvat | N6: Estimated End Date | P6: 46657
B7: Prime | D7: CN | H7: Type | J7: CMS | N7: Report Month | P7: 2026-2
B8: Currency | D8: USD | H8: Sell Value (USD) | N8: Country | P8: Panamá
B11: Major Events
B12: Date | D12: Event | F12: Readiness | H12: Risk Factor | J12: Obs
D13: Stock Counts
D14: Roll-Out
D15: Reclassifications
D16: Change Requests
D17: etc..
B26: Additional Comments
B27: Real Tickets (Incidents/UR) raised 27 vs 30(Range 3)

Sheet MX
C1: MX Financials | W1: Number of lines | X1: Period of the month reported | Y1: Period after month reported including | Z1: Period after month reported excluding | AA1: Period after month reported until end date | AB1: Sell Value if T&M | AC1: Sell value future | AD1: Sell value past
W2: =(YEAR(Summary!P6)-YEAR(Summary!P4))*12+MONTH(Summary!P6)-MONTH(Summary!P4)+1 -> 25
A3: Select Report Month | B3: Month | C3: Year | D3: Year-Month | E3: Start Date | F3: Plan End Date | G3: Estimate End Date | H3: Status | I3: Sell Value | J3: Effort | K3: Timesheet | L3: OTS (Snapshot) | M3: Allocations | N3: Plan Tickets | O3: Real Tickets | P3: Total Sell Value | Q3: Total Sell Effort | R3: Total Spent Effort | S3: Total Sell Tickets | T3: Total Real Tickets | U3: % Deviation | V3: % Ticket Deviation | W3: # ID
A4: =CONCATENATE(C4,"-",B4) -> 2025-9 | B4: =MONTH(Summary!P4) -> 9 | C4: =YEAR(Summary!P4) -> 2025 | D4: =CONCATENATE(C4,"-",B4) -> 2025-9 | E4: =+IF($B4="","",Summary!$P$4) -> 45929 | F4: =+IF($B4="","",Summary!$P$5) -> 46657 | G4: =+IF($B4="","",Summary!$P$6) -> 46657 | H4: =+IF($B4="","",IF(U4<-15%,"Red",IF(U4<0%,"Amber","Green"))) -> Green | N4: =O4 -> 0 | O4: 0 | P4: =I4 -> 0 | Q4: =J4 -> 0 | R4: =K4 -> 0 | S4: =N4 -> 0 | T4: =O4 -> 0 | U4: =IF(Q4=0,0,IF(K4<>"",(Q4-(R4+L4))/Q4,U3)) -> 0 | V4: =IF(S4=0,0,IF(O4<>"",(S4-(T4))/S4,V3)) -> 0 | W4: 1 | X4: =+IF((VLOOKUP(A4,List!B:C,2,0)-VLOOKUP(Summary!$P$7,List!B:C,2,0))=0,1,"") | Y4: =+IF((VLOOKUP(A4,List!B:C,2,0)-VLOOKUP(Summary!$P$7,List!B:C,2,0))>=0,1,"") | Z4: =+IF((VLOOKUP(A4,List!B:C,2,0)-VLOOKUP(Summary!$P$7,List!B:C,2,0))>0,1,"") | AA4: =+IFERROR(IF(Z4="","",IF(YEAR(G4)>C4,1,IF(YEAR(G4)=C4,IF(MONTH(G4)>=B4,1,2)))),2) | AB4: =+IF(AA4="","",IF(Summary!$J$7="Fixed Price","",IF(M4="",IF(I4="","",1),""))) | AC4: =+IFERROR(I4*AA4,0) -> 0 | AD4: =+IF(AA4="",+IF(N4>#REF!,#REF!,IF(N4>#REF!,#REF!,IF(N4>#REF!,#REF!,IF(N4>#REF!,#REF!,IF(N4>#REF!,#REF!,IF(N4>#REF!,#REF!,IF(N4>#REF!,#REF!,IF(N4>#REF!,#REF!,#REF!)))))))),0) -> #REF!
A5: =CONCATENATE(C5,"-",B5) -> 2025-10 | B5: =IF(W5<=$W$2,IF(B4>11,1,B4+1),"") -> 10 | C5: =IF(W5<=$W$2,IF(B4>11,C4+1,C4),"") -> 2025 | D5: =CONCATENATE(C5,"-",B5) -> 2025-10 | E5: =+IF($B5="","",Summary!$P$4) -> 45929 | F5: =+IF($B5="","",Summary!$P$5) -> 46657 | G5: =+IF($B5="","",Summary!$P$6) -> 46657 | H5: =+IF($B5="","",IF(U5<-15%,"Red",IF(U5<0%,"Amber","Green"))) -> Green | I5: 0 | J5: 0 | K5: 0 | M5: 0 | N5: 0 | O5: 0 | P5: =I5+P4 -> 0 | Q5: =Q4+J5 -> 0 | R5: =K5+R4 -> 0 | S5: =N5+S4 -> 0 | T5: =O5+T4 -> 0 | U5: =IF(Q5=0,0,IF(K5<>"",(Q5-(R5+L5))/Q5,U4)) -> 0 | V5: =IF(S5=0,0,IF(O5<>"",(S5-(T5))/S5,V4)) -> 0 | W5: 2 | X5: =+IF((VLOOKUP(A5,List!B:C,2,0)-VLOOKUP(Summary!$P$7,List!B:C,2,0))=0,1,"") | Y5: =+IF((VLOOKUP(A5,List!B:C,2,0)-VLOOKUP(Summary!$P$7,List!B:C,2,0))>=0,1,"") | Z5: =+IF((VLOOKUP(A5,List!B:C,2,0)-VLOOKUP(Summary!$P$7,List!B:C,2,0))>0,1,"") | AA5: =+IFERROR(IF(Z5="","",IF(YEAR(G5)>C5,1,IF(YEAR(G5)=C5,IF(MONTH(G5)>=B5,1,2)))),2) | AB5: =+IF(AA5="","",IF(Summary!$J$7="Fixed Price","",IF(M5="",IF(I5="","",1),""))) | AC5: =+IFERROR(I5*AA5,0) -> 0 | AD5: =+IF(AA5="",+IF(N5>#REF!,#REF!,IF(N5>#REF!,#REF!,IF(N5>#REF!,#REF!,IF(N5>#REF!,#REF!,IF(N5>#REF!,#REF!,IF(N5>#REF!,#REF!,IF(N5>#REF!,#REF!,IF(N5>#REF!,#REF!,#REF!)))))))),0) -> #REF!
A6: =CONCATENATE(C6,"-",B6) -> 2025-11 | B6: =IF(W6<=$W$2,IF(B5>11,1,B5+1),"") -> 11 | C6: =IF(W6<=$W$2,IF(B5>11,C5+1,C5),"") -> 2025 | D6: =CONCATENATE(C6,"-",B6) -> 2025-11 | E6: =+IF($B6="","",Summary!$P$4) -> 45929 | F6: =+IF($B6="","",Summary!$P$5) -> 46657 | G6: =+IF($B6="","",Summary!$P$6) -> 46657 | H6: =+IF($B6="","",IF(U6<-15%,"Red",IF(U6<0%,"Amber","Green"))) -> Green | I6: 10071.35 | J6: 17 | K6: 16.5 | M6: 17 | N6: 20 | O6: 20 | P6: =I6+P5 -> 10071.35 | Q6: =Q5+J6 -> 17 | R6: =K6+R5 -> 16.5 | S6: =N6+S5 -> 20 | T6: =O6+T5 -> 20 | U6: =IF(Q6=0,0,IF(K6<>"",(Q6-(R6+L6))/Q6,U5)) -> 0.029411765 | V6: =IF(S6=0,0,IF(O6<>"",(S6-(T6))/S6,V5)) -> 0 | W6: 3 | X6: =+IF((VLOOKUP(A6,List!B:C,2,0)-VLOOKUP(Summary!$P$7,List!B:C,2,0))=0,1,"") | Y6: =+IF((VLOOKUP(A6,List!B:C,2,0)-VLOOKUP(Summary!$P$7,List!B:C,2,0))>=0,1,"") | Z6: =+IF((VLOOKUP(A6,List!B:C,2,0)-VLOOKUP(Summary!$P$7,List!B:C,2,0))>0,1,"") | AA6: =+IFERROR(IF(Z6="","",IF(YEAR(G6)>C6,1,IF(YEAR(G6)=C6,IF(MONTH(G6)>=B6,1,2)))),2) | AB6: =+IF(AA6="","",IF(Summary!$J$7="Fixed Price","",IF(M6="",IF(I6="","",1),""))) | AC6: =+IFERROR(I6*AA6,0) -> 0 | AD6: =+IF(AA6="",+IF(N6>#REF!,#REF!,IF(N6>#REF!,#REF!,IF(N6>#REF!,#REF!,IF(N6>#REF!,#REF!,IF(N6>#REF!,#REF!,IF(N6>#REF!,#REF!,IF(N6>#REF!,#REF!,IF(N6>#REF!,#REF!,#REF!)))))))),0) -> #REF!
A7: =CONCATENATE(C7,"-",B7) -> 2025-12 | B7: =IF(W7<=$W$2,IF(B6>11,1,B6+1),"") -> 12 | C7: =IF(W7<=$W$2,IF(B6>11,C6+1,C6),"") -> 2025 | D7: =CONCATENATE(C7,"-",B7) -> 2025-12 | E7: =+IF($B7="","",Summary!$P$4) -> 45929 | F7: =+IF($B7="","",Summary!$P$5) -> 46657 | G7: =+IF($B7="","",Summary!$P$6) -> 46657 | H7: =+IF($B7="","",IF(U7<-15%,"Red",IF(U7<0%,"Amber","Green"))) -> Green | I7: 10071.35 | J7: 17 | K7: 14.2 | M7: 17 | N7: 20 | O7: 16 | P7: =I7+P6 -> 20142.7 | Q7: =Q6+J7 -> 34 | R7: =K7+R6 -> 30.7 | S7: =N7+S6 -> 40 | T7: =O7+T6 -> 36 | U7: =IF(Q7=0,0,IF(K7<>"",(Q7-(R7+L7))/Q7,U6)) -> 0.097058824 | V7: =IF(S7=0,0,IF(O7<>"",(S7-(T7))/S7,V6)) -> 0.1 | W7: 4 | X7: =+IF((VLOOKUP(A7,List!B:C,2,0)-VLOOKUP(Summary!$P$7,List!B:C,2,0))=0,1,"") | Y7: =+IF((VLOOKUP(A7,List!B:C,2,0)-VLOOKUP(Summary!$P$7,List!B:C,2,0))>=0,1,"") | Z7: =+IF((VLOOKUP(A7,List!B:C,2,0)-VLOOKUP(Summary!$P$7,List!B:C,2,0))>0,1,"") | AA7: =+IFERROR(IF(Z7="","",IF(YEAR(G7)>C7,1,IF(YEAR(G7)=C7,IF(MONTH(G7)>=B7,1,2)))),2) | AB7: =+IF(AA7="","",IF(Summary!$J$7="Fixed Price","",IF(M7="",IF(I7="","",1),""))) | AC7: =+IFERROR(I7*AA7,0) -> 0 | AD7: =+IF(AA7="",+IF(N7>#REF!,#REF!,IF(N7>#REF!,#REF!,IF(N7>#REF!,#REF!,IF(N7>#REF!,#REF!,IF(N7>#REF!,#REF!,IF(N7>#REF!,#REF!,IF(N7>#REF!,#REF!,IF(N7>#REF!,#REF!,#REF!)))))))),0) -> #REF!
A8: =CONCATENATE(C8,"-",B8) -> 2026-1 | B8: =IF(W8<=$W$2,IF(B7>11,1,B7+1),"") -> 1 | C8: =IF(W8<=$W$2,IF(B7>11,C7+1,C7),"") -> 2026 | D8: =CONCATENATE(C8,"-",B8) -> 2026-1 | E8: =+IF($B8="","",Summary!$P$4) -> 45929 | F8: =+IF($B8="","",Summary!$P$5) -> 46657 | G8: =+IF($B8="","",Summary!$P$6) -> 46657 | H8: =+IF($B8="","",IF(U8<-15%,"Red",IF(U8<0%,"Amber","Green"))) -> Green | I8: =10071.35+151.61*3 -> 10526.18 | J8: 17 | K8: 12.6 | M8: 17 | N8: 20 | O8: 23 | P8: =I8+P7 -> 30668.88 | Q8: =Q7+J8 -> 51 | R8: =K8+R7 -> 43.3 | S8: =N8+S7 -> 60 | T8: =O8+T7 -> 59 | U8: =IF(Q8=0,0,IF(K8<>"",(Q8-(R8+L8))/Q8,U7)) -> 0.15098039 | V8: =IF(S8=0,0,IF(O8<>"",(S8-(T8))/S8,V7)) -> 0.016666667 | W8: 5 | X8: =+IF((VLOOKUP(A8,List!B:C,2,0)-VLOOKUP(Summary!$P$7,List!B:C,2,0))=0,1,"") | Y8: =+IF((VLOOKUP(A8,List!B:C,2,0)-VLOOKUP(Summary!$P$7,List!B:C,2,0))>=0,1,"") | Z8: =+IF((VLOOKUP(A8,List!B:C,2,0)-VLOOKUP(Summary!$P$7,List!B:C,2,0))>0,1,"") | AA8: =+IFERROR(IF(Z8="","",IF(YEAR(G8)>C8,1,IF(YEAR(G8)=C8,IF(MONTH(G8)>=B8,1,2)))),2) | AB8: =+IF(AA8="","",IF(Summary!$J$7="Fixed Price","",IF(M8="",IF(I8="","",1),""))) | AC8: =+IFERROR(I8*AA8,0) -> 0 | AD8: =+IF(AA8="",+IF(N8>#REF!,#REF!,IF(N8>#REF!,#REF!,IF(N8>#REF!,#REF!,IF(N8>#REF!,#REF!,IF(N8>#REF!,#REF!,IF(N8>#REF!,#REF!,IF(N8>#REF!,#REF!,IF(N8>#REF!,#REF!,#REF!)))))))),0) -> #REF!
A9: =CONCATENATE(C9,"-",B9) -> 2026-2 | B9: =IF(W9<=$W$2,IF(B8>11,1,B8+1),"") -> 2 | C9: =IF(W9<=$W$2,IF(B8>11,C8+1,C8),"") -> 2026 | D9: =CONCATENATE(C9,"-",B9) -> 2026-2 | E9: =+IF($B9="","",Summary!$P$4) -> 45929 | F9: =+IF($B9="","",Summary!$P$5) -> 46657 | G9: =+IF($B9="","",Summary!$P$6) -> 46657 | H9: =+IF($B9="","",IF(U9<-15%,"Red",IF(U9<0%,"Amber","Green"))) -> Green | I9: 12843 | J9: 23.25 | K9: 9.19 | M9: 23.3 | N9: 30 | O9: 27 | P9: =I9+P8 -> 43511.88 | Q9: =Q8+J9 -> 74.25 | R9: =K9+R8 -> 52.49 | S9: =N9+S8 -> 90 | T9: =O9+T8 -> 86 | U9: =IF(Q9=0,0,IF(K9<>"",(Q9-(R9+L9))/Q9,U8)) -> 0.29306397 | V9: =IF(S9=0,0,IF(O9<>"",(S9-(T9))/S9,V8)) -> 0.044444444 | W9: 6 | X9: =+IF((VLOOKUP(A9,List!B:C,2,0)-VLOOKUP(Summary!$P$7,List!B:C,2,0))=0,1,"") -> 1 | Y9: =+IF((VLOOKUP(A9,List!B:C,2,0)-VLOOKUP(Summary!$P$7,List!B:C,2,0))>=0,1,"") -> 1 | Z9: =+IF((VLOOKUP(A9,List!B:C,2,0)-VLOOKUP(Summary!$P$7,List!B:C,2,0))>0,1,"") | AA9: =+IFERROR(IF(Z9="","",IF(YEAR(G9)>C9,1,IF(YEAR(G9)=C9,IF(MONTH(G9)>=B9,1,2)))),2) | AB9: =+IF(AA9="","",IF(Summary!$J$7="Fixed Price","",IF(M9="",IF(I9="","",1),""))) | AC9: =+IFERROR(I9*AA9,0) -> 0 | AD9: =+IF(AA9="",+IF(N9>#REF!,#REF!,IF(N9>#REF!,#REF!,IF(N9>#REF!,#REF!,IF(N9>#REF!,#REF!,IF(N9>#REF!,#REF!,IF(N9>#REF!,#REF!,IF(N9>#REF!,#REF!,IF(N9>#REF!,#REF!,#REF!)))))))),0) -> #REF!
A10: =CONCATENATE(C10,"-",B10) -> 2026-3 | B10: =IF(W10<=$W$2,IF(B9>11,1,B9+1),"") -> 3 | C10: =IF(W10<=$W$2,IF(B9>11,C9+1,C9),"") -> 2026 | D10: =CONCATENATE(C10,"-",B10) -> 2026-3 | E10: =+IF($B10="","",Summary!$P$4) -> 45929 | F10: =+IF($B10="","",Summary!$P$5) -> 46657 | G10: =+IF($B10="","",Summary!$P$6) -> 46657 | H10: =+IF($B10="","",IF(U10<-15%,"Red",IF(U10<0%,"Amber","Green"))) -> Green | I10: 8693.1 | J10: 11 | M10: 11 | N10: =O10 -> 0 | O10: 0 | P10: =I10+P9 -> 52204.98 | Q10: =Q9+J10 -> 85.25 | R10: =K10+R9 -> 52.49 | S10: =N10+S9 -> 90 | T10: =O10+T9 -> 86 | U10: =IF(Q10=0,0,IF(K10<>"",(Q10-(R10+L10))/Q10,U9)) -> 0.29306397 | V10: =IF(S10=0,0,IF(O10<>"",(S10-(T10))/S10,V9)) -> 0.044444444 | W10: 7 | X10: =+IF((VLOOKUP(A10,List!B:C,2,0)-VLOOKUP(Summary!$P$7,List!B:C,2,0))=0,1,"") | Y10: =+IF((VLOOKUP(A10,List!B:C,2,0)-VLOOKUP(Summary!$P$7,List!B:C,2,0))>=0,1,"") -> 1 | Z10: =+IF((VLOOKUP(A10,List!B:C,2,0)-VLOOKUP(Summary!$P$7,List!B:C,2,0))>0,1,"") -> 1 | AA10: =+IFERROR(IF(Z10="","",IF(YEAR(G10)>C10,1,IF(YEAR(G10)=C10,IF(MONTH(G10)>=B10,1,2)))),2) -> 1 | AB10: =+IF(AA10="","",IF(Summary!$J$7="Fixed Price","",IF(M10="",IF(I10="","",1),""))) | AC10: =+IFERROR(I10*AA10,0) -> 8693.1 | AD10: =+IF(AA10="",+IF(N10>#REF!,#REF!,IF(N10>#REF!,#REF!,IF(N10>#REF!,#REF!,IF(N10>#REF!,#REF!,IF(N10>#REF!,#REF!,IF(N10>#REF!,#REF!,IF(N10>#REF!,#REF!,IF(N10>#REF!,#REF!,#REF!)))))))),0) -> 0
A11: =CONCATENATE(C11,"-",B11) -> 2026-4 | B11: =IF(W11<=$W$2,IF(B10>11,1,B10+1),"") -> 4 | C11: =IF(W11<=$W$2,IF(B10>11,C10+1,C10),"") -> 2026 | D11: =CONCATENATE(C11,"-",B11) -> 2026-4 | E11: =+IF($B11="","",Summary!$P$4) -> 45929 | F11: =+IF($B11="","",Summary!$P$5) -> 46657 | G11: =+IF($B11="","",Summary!$P$6) -> 46657 | H11: =+IF($B11="","",IF(U11<-15%,"Red",IF(U11<0%,"Amber","Green"))) -> Green | I11: 8693.1 | J11: 11 | M11: 11 | N11: =O11 -> 0 | O11: 0 | P11: =I11+P10 -> 60898.08 | Q11: =Q10+J11 -> 96.25 | R11: =K11+R10 -> 52.49 | S11: =N11+S10 -> 90 | T11: =O11+T10 -> 86 | U11: =IF(Q11=0,0,IF(K11<>"",(Q11-(R11+L11))/Q11,U10)) -> 0.29306397 | V11: =IF(S11=0,0,IF(O11<>"",(S11-(T11))/S11,V10)) -> 0.044444444 | W11: 8 | X11: =+IF((VLOOKUP(A11,List!B:C,2,0)-VLOOKUP(Summary!$P$7,List!B:C,2,0))=0,1,"") | Y11: =+IF((VLOOKUP(A11,List!B:C,2,0)-VLOOKUP(Summary!$P$7,List!B:C,2,0))>=0,1,"") -> 1 | Z11: =+IF((VLOOKUP(A11,List!B:C,2,0)-VLOOKUP(Summary!$P$7,List!B:C,2,0))>0,1,"") -> 1 | AA11: =+IFERROR(IF(Z11="","",IF(YEAR(G11)>C11,1,IF(YEAR(G11)=C11,IF(MONTH(G11)>=B11,1,2)))),2) -> 1 | AB11: =+IF(AA11="","",IF(Summary!$J$7="Fixed Price","",IF(M11="",IF(I11="","",1),""))) | AC11: =+IFERROR(I11*AA11,0) -> 8693.1 | AD11: =+IF(AA11="",+IF(N11>#REF!,#REF!,IF(N11>#REF!,#REF!,IF(N11>#REF!,#REF!,IF(N11>#REF!,#REF!,IF(N11>#REF!,#REF!,IF(N11>#REF!,#REF!,IF(N11>#REF!,#REF!,IF(N11>#REF!,#REF!,#REF!)))))))),0) -> 0
A12: =CONCATENATE(C12,"-",B12) -> 2026-5 | B12: =IF(W12<=$W$2,IF(B11>11,1,B11+1),"") -> 5 | C12: =IF(W12<=$W$2,IF(B11>11,C11+1,C11),"") -> 2026 | D12: =CONCATENATE(C12,"-",B12) -> 2026-5 | E12: =+IF($B12="","",Summary!$P$4) -> 45929 | F12: =+IF($B12="","",Summary!$P$5) -> 46657 | G12: =+IF($B12="","",Summary!$P$6) -> 46657 | H12: =+IF($B12="","",IF(U12<-15%,"Red",IF(U12<0%,"Amber","Green"))) -> Green | I12: 8693.1 | J12: 11 | M12: 11 | N12: =O12 -> 0 | O12: 0 | P12: =I12+P11 -> 69591.18 | Q12: =Q11+J12 -> 107.25 | R12: =K12+R11 -> 52.49 | S12: =N12+S11 -> 90 | T12: =O12+T11 -> 86 | U12: =IF(Q12=0,0,IF(K12<>"",(Q12-(R12+L12))/Q12,U11)) -> 0.29306397 | V12: =IF(S12=0,0,IF(O12<>"",(S12-(T12))/S12,V11)) -> 0.044444444 | W12: 9 | X12: =+IF((VLOOKUP(A12,List!B:C,2,0)-VLOOKUP(Summary!$P$7,List!B:C,2,0))=0,1,"") | Y12: =+IF((VLOOKUP(A12,List!B:C,2,0)-VLOOKUP(Summary!$P$7,List!B:C,2,0))>=0,1,"") -> 1 | Z12: =+IF((VLOOKUP(A12,List!B:C,2,0)-VLOOKUP(Summary!$P$7,List!B:C,2,0))>0,1,"") -> 1 | AA12: =+IFERROR(IF(Z12="","",IF(YEAR(G12)>C12,1,IF(YEAR(G12)=C12,IF(MONTH(G12)>=B12,1,2)))),2) -> 1 | AB12: =+IF(AA12="","",IF(Summary!$J$7="Fixed Price","",IF(M12="",IF(I12="","",1),""))) | AC12: =+IFERROR(I12*AA12,0) -> 8693.1 | AD12: =+IF(AA12="",+IF(N12>#REF!,#REF!,IF(N12>#REF!,#REF!,IF(N12>#REF!,#REF!,IF(N12>#REF!,#REF!,IF(N12>#REF!,#REF!,IF(N12>#REF!,#REF!,IF(N12>#REF!,#REF!,IF(N12>#REF!,#REF!,#REF!)))))))),0) -> 0
A13: =CONCATENATE(C13,"-",B13) -> 2026-6 | B13: =IF(W13<=$W$2,IF(B12>11,1,B12+1),"") -> 6 | C13: =IF(W13<=$W$2,IF(B12>11,C12+1,C12),"") -> 2026 | D13: =CONCATENATE(C13,"-",B13) -> 2026-6 | E13: =+IF($B13="","",Summary!$P$4) -> 45929 | F13: =+IF($B13="","",Summary!$P$5) -> 46657 | G13: =+IF($B13="","",Summary!$P$6) -> 46657 | H13: =+IF($B13="","",IF(U13<-15%,"Red",IF(U13<0%,"Amber","Green"))) -> Green | I13: 8693.1 | J13: 11 | M13: 11 | N13: =O13 -> 0 | O13: 0 | P13: =I13+P12 -> 78284.28 | Q13: =Q12+J13 -> 118.25 | R13: =K13+R12 -> 52.49 | S13: =N13+S12 -> 90 | T13: =O13+T12 -> 86 | U13: =IF(Q13=0,0,IF(K13<>"",(Q13-(R13+L13))/Q13,U12)) -> 0.29306397 | V13: =IF(S13=0,0,IF(O13<>"",(S13-(T13))/S13,V12)) -> 0.044444444 | W13: 10 | X13: =+IF((VLOOKUP(A13,List!B:C,2,0)-VLOOKUP(Summary!$P$7,List!B:C,2,0))=0,1,"") | Y13: =+IF((VLOOKUP(A13,List!B:C,2,0)-VLOOKUP(Summary!$P$7,List!B:C,2,0))>=0,1,"") -> 1 | Z13: =+IF((VLOOKUP(A13,List!B:C,2,0)-VLOOKUP(Summary!$P$7,List!B:C,2,0))>0,1,"") -> 1 | AA13: =+IFERROR(IF(Z13="","",IF(YEAR(G13)>C13,1,IF(YEAR(G13)=C13,IF(MONTH(G13)>=B13,1,2)))),2) -> 1 | AB13: =+IF(AA13="","",IF(Summary!$J$7="Fixed Price","",IF(M13="",IF(I13="","",1),""))) | AC13: =+IFERROR(I13*AA13,0) -> 8693.1 | AD13: =+IF(AA13="",+IF(N13>#REF!,#REF!,IF(N13>#REF!,#REF!,IF(N13>#REF!,#REF!,IF(N13>#REF!,#REF!,IF(N13>#REF!,#REF!,IF(N13>#REF!,#REF!,IF(N13>#REF!,#REF!,IF(N13>#REF!,#REF!,#REF!)))))))),0) -> 0
A14: =CONCATENATE(C14,"-",B14) -> 2026-7 | B14: =IF(W14<=$W$2,IF(B13>11,1,B13+1),"") -> 7 | C14: =IF(W14<=$W$2,IF(B13>11,C13+1,C13),"") -> 2026 | D14: =CONCATENATE(C14,"-",B14) -> 2026-7 | E14: =+IF($B14="","",Summary!$P$4) -> 45929 | F14: =+IF($B14="","",Summary!$P$5) -> 46657 | G14: =+IF($B14="","",Summary!$P$6) -> 46657 | H14: =+IF($B14="","",IF(U14<-15%,"Red",IF(U14<0%,"Amber","Green"))) -> Green | I14: 8693.1 | J14: 11 | M14: 11 | N14: =O14 -> 0 | O14: 0 | P14: =I14+P13 -> 86977.38 | Q14: =Q13+J14 -> 129.25 | R14: =K14+R13 -> 52.49 | S14: =N14+S13 -> 90 | T14: =O14+T13 -> 86 | U14: =IF(Q14=0,0,IF(K14<>"",(Q14-(R14+L14))/Q14,U13)) -> 0.29306397 | V14: =IF(S14=0,0,IF(O14<>"",(S14-(T14))/S14,V13)) -> 0.044444444 | W14: 11 | X14: =+IF((VLOOKUP(A14,List!B:C,2,0)-VLOOKUP(Summary!$P$7,List!B:C,2,0))=0,1,"") | Y14: =+IF((VLOOKUP(A14,List!B:C,2,0)-VLOOKUP(Summary!$P$7,List!B:C,2,0))>=0,1,"") -> 1 | Z14: =+IF((VLOOKUP(A14,List!B:C,2,0)-VLOOKUP(Summary!$P$7,List!B:C,2,0))>0,1,"") -> 1 | AA14: =+IFERROR(IF(Z14="","",IF(YEAR(G14)>C14,1,IF(YEAR(G14)=C14,IF(MONTH(G14)>=B14,1,2)))),2) -> 1 | AB14: =+IF(AA14="","",IF(Summary!$J$7="Fixed Price","",IF(M14="",IF(I14="","",1),""))) | AC14: =+IFERROR(I14*AA14,0) -> 8693.1 | AD14: =+IF(AA14="",+IF(N14>#REF!,#REF!,IF(N14>#REF!,#REF!,IF(N14>#REF!,#REF!,IF(N14>#REF!,#REF!,IF(N14>#REF!,#REF!,IF(N14>#REF!,#REF!,IF(N14>#REF!,#REF!,IF(N14>#REF!,#REF!,#REF!)))))))),0) -> 0
A15: =CONCATENATE(C15,"-",B15) -> 2026-8 | B15: =IF(W15<=$W$2,IF(B14>11,1,B14+1),"") -> 8 | C15: =IF(W15<=$W$2,IF(B14>11,C14+1,C14),"") -> 2026 | D15: =CONCATENATE(C15,"-",B15) -> 2026-8 | E15: =+IF($B15="","",Summary!$P$4) -> 45929 | F15: =+IF($B15="","",Summary!$P$5) -> 46657 | G15: =+IF($B15="","",Summary!$P$6) -> 46657 | H15: =+IF($B15="","",IF(U15<-15%,"Red",IF(U15<0%,"Amber","Green"))) -> Green | I15: 8693.1 | J15: 11 | M15: 11 | N15: =O15 -> 0 | O15: 0 | P15: =I15+P14 -> 95670.48 | Q15: =Q14+J15 -> 140.25 | R15: =K15+R14 -> 52.49 | S15: =N15+S14 -> 90 | T15: =O15+T14 -> 86 | U15: =IF(Q15=0,0,IF(K15<>"",(Q15-(R15+L15))/Q15,U14)) -> 0.29306397 | V15: =IF(S15=0,0,IF(O15<>"",(S15-(T15))/S15,V14)) -> 0.044444444 | W15: 12 | X15: =+IF((VLOOKUP(A15,List!B:C,2,0)-VLOOKUP(Summary!$P$7,List!B:C,2,0))=0,1,"") | Y15: =+IF((VLOOKUP(A15,List!B:C,2,0)-VLOOKUP(Summary!$P$7,List!B:C,2,0))>=0,1,"") -> 1 | Z15: =+IF((VLOOKUP(A15,List!B:C,2,0)-VLOOKUP(Summary!$P$7,List!B:C,2,0))>0,1,"") -> 1 | AA15: =+IFERROR(IF(Z15="","",IF(YEAR(G15)>C15,1,IF(YEAR(G15)=C15,IF(MONTH(G15)>=B15,1,2)))),2) -> 1 | AB15: =+IF(AA15="","",IF(Summary!$J$7="Fixed Price","",IF(M15="",IF(I15="","",1),""))) | AC15: =+IFERROR(I15*AA15,0) -> 8693.1 | AD15: =+IF(AA15="",+IF(N15>#REF!,#REF!,IF(N15>#REF!,#REF!,IF(N15>#REF!,#REF!,IF(N15>#REF!,#REF!,IF(N15>#REF!,#REF!,IF(N15>#REF!,#REF!,IF(N15>#REF!,#REF!,IF(N15>#REF!,#REF!,#REF!)))))))),0) -> 0
A16: =CONCATENATE(C16,"-",B16) -> 2026-9 | B16: =IF(W16<=$W$2,IF(B15>11,1,B15+1),"") -> 9 | C16: =IF(W16<=$W$2,IF(B15>11,C15+1,C15),"") -> 2026 | D16: =CONCATENATE(C16,"-",B16) -> 2026-9 | E16: =+IF($B16="","",Summary!$P$4) -> 45929 | F16: =+IF($B16="","",Summary!$P$5) -> 46657 | G16: =+IF($B16="","",Summary!$P$6) -> 46657 | H16: =+IF($B16="","",IF(U16<-15%,"Red",IF(U16<0%,"Amber","Green"))) -> Green | I16: 8693.1 | J16: 11 | M16: 11 | N16: =O16 -> 0 | O16: 0 | P16: =I16+P15 -> 104363.58 | Q16: =Q15+J16 -> 151.25 | R16: =K16+R15 -> 52.49 | S16: =N16+S15 -> 90 | T16: =O16+T15 -> 86 | U16: =IF(Q16=0,0,IF(K16<>"",(Q16-(R16+L16))/Q16,U15)) -> 0.29306397 | V16: =IF(S16=0,0,IF(O16<>"",(S16-(T16))/S16,V15)) -> 0.044444444 | W16: 13 | X16: =+IF((VLOOKUP(A16,List!B:C,2,0)-VLOOKUP(Summary!$P$7,List!B:C,2,0))=0,1,"") | Y16: =+IF((VLOOKUP(A16,List!B:C,2,0)-VLOOKUP(Summary!$P$7,List!B:C,2,0))>=0,1,"") -> 1 | Z16: =+IF((VLOOKUP(A16,List!B:C,2,0)-VLOOKUP(Summary!$P$7,List!B:C,2,0))>0,1,"") -> 1 | AA16: =+IFERROR(IF(Z16="","",IF(YEAR(G16)>C16,1,IF(YEAR(G16)=C16,IF(MONTH(G16)>=B16,1,2)))),2) -> 1 | AB16: =+IF(AA16="","",IF(Summary!$J$7="Fixed Price","",IF(M16="",IF(I16="","",1),""))) | AC16: =+IFERROR(I16*AA16,0) -> 8693.1 | AD16: =+IF(AA16="",+IF(N16>#REF!,#REF!,IF(N16>#REF!,#REF!,IF(N16>#REF!,#REF!,IF(N16>#REF!,#REF!,IF(N16>#REF!,#REF!,IF(N16>#REF!,#REF!,IF(N16>#REF!,#REF!,IF(N16>#REF!,#REF!,#REF!)))))))),0) -> 0
A17: =CONCATENATE(C17,"-",B17) -> 2026-10 | B17: =IF(W17<=$W$2,IF(B16>11,1,B16+1),"") -> 10 | C17: =IF(W17<=$W$2,IF(B16>11,C16+1,C16),"") -> 2026 | D17: =CONCATENATE(C17,"-",B17) -> 2026-10 | E17: =+IF($B17="","",Summary!$P$4) -> 45929 | F17: =+IF($B17="","",Summary!$P$5) -> 46657 | G17: =+IF($B17="","",Summary!$P$6) -> 46657 | H17: =+IF($B17="","",IF(U17<-15%,"Red",IF(U17<0%,"Amber","Green"))) -> Green | I17: 8693.1 | J17: 11 | M17: 11 | N17: =O17 -> 0 | O17: 0 | P17: =I17+P16 -> 113056.68 | Q17: =Q16+J17 -> 162.25 | R17: =K17+R16 -> 52.49 | S17: =N17+S16 -> 90 | T17: =O17+T16 -> 86 | U17: =IF(Q17=0,0,IF(K17<>"",(Q17-(R17+L17))/Q17,U16)) -> 0.29306397 | V17: =IF(S17=0,0,IF(O17<>"",(S17-(T17))/S17,V16)) -> 0.044444444 | W17: 14 | X17: =+IF((VLOOKUP(A17,List!B:C,2,0)-VLOOKUP(Summary!$P$7,List!B:C,2,0))=0,1,"") | Y17: =+IF((VLOOKUP(A17,List!B:C,2,0)-VLOOKUP(Summary!$P$7,List!B:C,2,0))>=0,1,"") -> 1 | Z17: =+IF((VLOOKUP(A17,List!B:C,2,0)-VLOOKUP(Summary!$P$7,List!B:C,2,0))>0,1,"") -> 1 | AA17: =+IFERROR(IF(Z17="","",IF(YEAR(G17)>C17,1,IF(YEAR(G17)=C17,IF(MONTH(G17)>=B17,1,2)))),2) -> 1 | AB17: =+IF(AA17="","",IF(Summary!$J$7="Fixed Price","",IF(M17="",IF(I17="","",1),""))) | AC17: =+IFERROR(I17*AA17,0) -> 8693.1 | AD17: =+IF(AA17="",+IF(N17>#REF!,#REF!,IF(N17>#REF!,#REF!,IF(N17>#REF!,#REF!,IF(N17>#REF!,#REF!,IF(N17>#REF!,#REF!,IF(N17>#REF!,#REF!,IF(N17>#REF!,#REF!,IF(N17>#REF!,#REF!,#REF!)))))))),0) -> 0
A18: =CONCATENATE(C18,"-",B18) -> 2026-11 | B18: =IF(W18<=$W$2,IF(B17>11,1,B17+1),"") -> 11 | C18: =IF(W18<=$W$2,IF(B17>11,C17+1,C17),"") -> 2026 | D18: =CONCATENATE(C18,"-",B18) -> 2026-11 | E18: =+IF($B18="","",Summary!$P$4) -> 45929 | F18: =+IF($B18="","",Summary!$P$5) -> 46657 | G18: =+IF($B18="","",Summary!$P$6) -> 46657 | H18: =+IF($B18="","",IF(U18<-15%,"Red",IF(U18<0%,"Amber","Green"))) -> Green | I18: 8693.1 | J18: 11 | M18: 11 | N18: =O18 -> 0 | O18: 0 | P18: =I18+P17 -> 121749.78 | Q18: =Q17+J18 -> 173.25 | R18: =K18+R17 -> 52.49 | S18: =N18+S17 -> 90 | T18: =O18+T17 -> 86 | U18: =IF(Q18=0,0,IF(K18<>"",(Q18-(R18+L18))/Q18,U17)) -> 0.29306397 | V18: =IF(S18=0,0,IF(O18<>"",(S18-(T18))/S18,V17)) -> 0.044444444 | W18: 15 | X18: =+IF((VLOOKUP(A18,List!B:C,2,0)-VLOOKUP(Summary!$P$7,List!B:C,2,0))=0,1,"") | Y18: =+IF((VLOOKUP(A18,List!B:C,2,0)-VLOOKUP(Summary!$P$7,List!B:C,2,0))>=0,1,"") -> 1 | Z18: =+IF((VLOOKUP(A18,List!B:C,2,0)-VLOOKUP(Summary!$P$7,List!B:C,2,0))>0,1,"") -> 1 | AA18: =+IFERROR(IF(Z18="","",IF(YEAR(G18)>C18,1,IF(YEAR(G18)=C18,IF(MONTH(G18)>=B18,1,2)))),2) -> 1 | AB18: =+IF(AA18="","",IF(Summary!$J$7="Fixed Price","",IF(M18="",IF(I18="","",1),""))) | AC18: =+IFERROR(I18*AA18,0) -> 8693.1 | AD18: =+IF(AA18="",+IF(N18>#REF!,#REF!,IF(N18>#REF!,#REF!,IF(N18>#REF!,#REF!,IF(N18>#REF!,#REF!,IF(N18>#REF!,#REF!,IF(N18>#REF!,#REF!,IF(N18>#REF!,#REF!,IF(N18>#REF!,#REF!,#REF!)))))))),0) -> 0
A19: =CONCATENATE(C19,"-",B19) -> 2026-12 | B19: =IF(W19<=$W$2,IF(B18>11,1,B18+1),"") -> 12 | C19: =IF(W19<=$W$2,IF(B18>11,C18+1,C18),"") -> 2026 | D19: =CONCATENATE(C19,"-",B19) -> 2026-12 | E19: =+IF($B19="","",Summary!$P$4) -> 45929 | F19: =+IF($B19="","",Summary!$P$5) -> 46657 | G19: =+IF($B19="","",Summary!$P$6) -> 46657 | H19: =+IF($B19="","",IF(U19<-15%,"Red",IF(U19<0%,"Amber","Green"))) -> Green | I19: 8693.1 | J19: 11 | M19: 11 | N19: =O19 -> 0 | O19: 0 | P19: =I19+P18 -> 130442.88 | Q19: =Q18+J19 -> 184.25 | R19: =K19+R18 -> 52.49 | S19: =N19+S18 -> 90 | T19: =O19+T18 -> 86 | U19: =IF(Q19=0,0,IF(K19<>"",(Q19-(R19+L19))/Q19,U18)) -> 0.29306397 | V19: =IF(S19=0,0,IF(O19<>"",(S19-(T19))/S19,V18)) -> 0.044444444 | W19: 16 | X19: =+IF((VLOOKUP(A19,List!B:C,2,0)-VLOOKUP(Summary!$P$7,List!B:C,2,0))=0,1,"") | Y19: =+IF((VLOOKUP(A19,List!B:C,2,0)-VLOOKUP(Summary!$P$7,List!B:C,2,0))>=0,1,"") -> 1 | Z19: =+IF((VLOOKUP(A19,List!B:C,2,0)-VLOOKUP(Summary!$P$7,List!B:C,2,0))>0,1,"") -> 1 | AA19: =+IFERROR(IF(Z19="","",IF(YEAR(G19)>C19,1,IF(YEAR(G19)=C19,IF(MONTH(G19)>=B19,1,2)))),2) -> 1 | AB19: =+IF(AA19="","",IF(Summary!$J$7="Fixed Price","",IF(M19="",IF(I19="","",1),""))) | AC19: =+IFERROR(I19*AA19,0) -> 8693.1 | AD19: =+IF(AA19="",+IF(N19>#REF!,#REF!,IF(N19>#REF!,#REF!,IF(N19>#REF!,#REF!,IF(N19>#REF!,#REF!,IF(N19>#REF!,#REF!,IF(N19>#REF!,#REF!,IF(N19>#REF!,#REF!,IF(N19>#REF!,#REF!,#REF!)))))))),0) -> 0
A20: =CONCATENATE(C20,"-",B20) -> 2027-1 | B20: =IF(W20<=$W$2,IF(B19>11,1,B19+1),"") -> 1 | C20: =IF(W20<=$W$2,IF(B19>11,C19+1,C19),"") -> 2027 | D20: =CONCATENATE(C20,"-",B20) -> 2027-1 | E20: =+IF($B20="","",Summary!$P$4) -> 45929 | F20: =+IF($B20="","",Summary!$P$5) -> 46657 | G20: =+IF($B20="","",Summary!$P$6) -> 46657 | H20: =+IF($B20="","",IF(U20<-15%,"Red",IF(U20<0%,"Amber","Green"))) -> Green | I20: 8693.1 | J20: 11 | M20: 11 | N20: =O20 -> 0 | O20: 0 | P20: =I20+P19 -> 139135.98 | Q20: =Q19+J20 -> 195.25 | R20: =K20+R19 -> 52.49 | S20: =N20+S19 -> 90 | T20: =O20+T19 -> 86 | U20: =IF(Q20=0,0,IF(K20<>"",(Q20-(R20+L20))/Q20,U19)) -> 0.29306397 | V20: =IF(S20=0,0,IF(O20<>"",(S20-(T20))/S20,V19)) -> 0.044444444 | W20: 17 | X20: =+IF((VLOOKUP(A20,List!B:C,2,0)-VLOOKUP(Summary!$P$7,List!B:C,2,0))=0,1,"") | Y20: =+IF((VLOOKUP(A20,List!B:C,2,0)-VLOOKUP(Summary!$P$7,List!B:C,2,0))>=0,1,"") -> 1 | Z20: =+IF((VLOOKUP(A20,List!B:C,2,0)-VLOOKUP(Summary!$P$7,List!B:C,2,0))>0,1,"") -> 1 | AA20: =+IFERROR(IF(Z20="","",IF(YEAR(G20)>C20,1,IF(YEAR(G20)=C20,IF(MONTH(G20)>=B20,1,2)))),2) -> 1 | AB20: =+IF(AA20="","",IF(Summary!$J$7="Fixed Price","",IF(M20="",IF(I20="","",1),""))) | AC20: =+IFERROR(I20*AA20,0) -> 8693.1 | AD20: =+IF(AA20="",+IF(N20>#REF!,#REF!,IF(N20>#REF!,#REF!,IF(N20>#REF!,#REF!,IF(N20>#REF!,#REF!,IF(N20>#REF!,#REF!,IF(N20>#REF!,#REF!,IF(N20>#REF!,#REF!,IF(N20>#REF!,#REF!,#REF!)))))))),0) -> 0
A21: =CONCATENATE(C21,"-",B21) -> 2027-2 | B21: =IF(W21<=$W$2,IF(B20>11,1,B20+1),"") -> 2 | C21: =IF(W21<=$W$2,IF(B20>11,C20+1,C20),"") -> 2027 | D21: =CONCATENATE(C21,"-",B21) -> 2027-2 | E21: =+IF($B21="","",Summary!$P$4) -> 45929 | F21: =+IF($B21="","",Summary!$P$5) -> 46657 | G21: =+IF($B21="","",Summary!$P$6) -> 46657 | H21: =+IF($B21="","",IF(U21<-15%,"Red",IF(U21<0%,"Amber","Green"))) -> Green | I21: 8693.1 | J21: 11 | M21: 11 | N21: =O21 -> 0 | O21: 0 | P21: =I21+P20 -> 147829.08 | Q21: =Q20+J21 -> 206.25 | R21: =K21+R20 -> 52.49 | S21: =N21+S20 -> 90 | T21: =O21+T20 -> 86 | U21: =IF(Q21=0,0,IF(K21<>"",(Q21-(R21+L21))/Q21,U20)) -> 0.29306397 | V21: =IF(S21=0,0,IF(O21<>"",(S21-(T21))/S21,V20)) -> 0.044444444 | W21: 18 | X21: =+IF((VLOOKUP(A21,List!B:C,2,0)-VLOOKUP(Summary!$P$7,List!B:C,2,0))=0,1,"") | Y21: =+IF((VLOOKUP(A21,List!B:C,2,0)-VLOOKUP(Summary!$P$7,List!B:C,2,0))>=0,1,"") -> 1 | Z21: =+IF((VLOOKUP(A21,List!B:C,2,0)-VLOOKUP(Summary!$P$7,List!B:C,2,0))>0,1,"") -> 1 | AA21: =+IFERROR(IF(Z21="","",IF(YEAR(G21)>C21,1,IF(YEAR(G21)=C21,IF(MONTH(G21)>=B21,1,2)))),2) -> 1 | AB21: =+IF(AA21="","",IF(Summary!$J$7="Fixed Price","",IF(M21="",IF(I21="","",1),""))) | AC21: =+IFERROR(I21*AA21,0) -> 8693.1 | AD21: =+IF(AA21="",+IF(N21>#REF!,#REF!,IF(N21>#REF!,#REF!,IF(N21>#REF!,#REF!,IF(N21>#REF!,#REF!,IF(N21>#REF!,#REF!,IF(N21>#REF!,#REF!,IF(N21>#REF!,#REF!,IF(N21>#REF!,#REF!,#REF!)))))))),0) -> 0
... A28: =CONCATENATE(C28,"-",B28) -> 2027-9 | B28: =IF(W28<=$W$2,IF(B27>11,1,B27+1),"") -> 9 | C28: =IF(W28<=$W$2,IF(B27>11,C27+1,C27),"") -> 2027 | D28: =CONCATENATE(C28,"-",B28) -> 2027-9 | E28: =+IF($B28="","",Summary!$P$4) -> 45929 | F28: =+IF($B28="","",Summary!$P$5) -> 46657 | G28: =+IF($B28="","",Summary!$P$6) -> 46657 | H28: =+IF($B28="","",IF(U28<-15%,"Red",IF(U28<0%,"Amber","Green"))) -> Green | I28: 8693.1 | J28: 11 | M28: 11 | N28: =O28 -> 0 | O28: 0 | P28: =I28+P27 -> 208680.78 | Q28: =Q27+J28 -> 283.25 | R28: =K28+R27 -> 52.49 | S28: =N28+S27 -> 90 | T28: =O28+T27 -> 86 | U28: =IF(Q28=0,0,IF(K28<>"",(Q28-(R28+L28))/Q28,U27)) -> 0.29306397 | V28: =IF(S28=0,0,IF(O28<>"",(S28-(T28))/S28,V27)) -> 0.044444444 | W28: 25 | X28: =+IF((VLOOKUP(A28,List!B:C,2,0)-VLOOKUP(Summary!$P$7,List!B:C,2,0))=0,1,"") | Y28: =+IF((VLOOKUP(A28,List!B:C,2,0)-VLOOKUP(Summary!$P$7,List!B:C,2,0))>=0,1,"") -> 1 | Z28: =+IF((VLOOKUP(A28,List!B:C,2,0)-VLOOKUP(Summary!$P$7,List!B:C,2,0))>0,1,"") -> 1 | AA28: =+IFERROR(IF(Z28="","",IF(YEAR(G28)>C28,1,IF(YEAR(G28)=C28,IF(MONTH(G28)>=B28,1,2)))),2) -> 1 | AB28: =+IF(AA28="","",IF(Summary!$J$7="Fixed Price","",IF(M28="",IF(I28="","",1),""))) | AC28: =+IFERROR(I28*AA28,0) -> 8693.1 | AD28: =+IF(AA28="",+IF(N28>#REF!,#REF!,IF(N28>#REF!,#REF!,IF(N28>#REF!,#REF!,IF(N28>#REF!,#REF!,IF(N28>#REF!,#REF!,IF(N28>#REF!,#REF!,IF(N28>#REF!,#REF!,IF(N28>#REF!,#REF!,#REF!)))))))),0) -> 0
A29: =CONCATENATE(C29,"-",B29) -> - | B29: =IF(W29<=$W$2,IF(B28>11,1,B28+1),"") | C29: =IF(W29<=$W$2,IF(B28>11,C28+1,C28),"") | D29: =CONCATENATE(C29,"-",B29) -> - | E29: =+IF($B29="","",Summary!$P$4) | F29: =+IF($B29="","",Summary!$P$5) | G29: =+IF($B29="","",Summary!$P$6) | H29: =+IF($B29="","",IF(U29<-15%,"Red",IF(U29<0%,"Amber","Green"))) | N29: =O29 -> 0 | O29: 0 | P29: =I29+P28 -> 208680.78 | Q29: =Q28+J29 -> 283.25 | R29: =K29+R28 -> 52.49 | S29: =N29+S28 -> 90 | T29: =O29+T28 -> 86 | U29: =IF(Q29=0,0,IF(K29<>"",(Q29-(R29+L29))/Q29,U28)) -> 0.29306397 | V29: =IF(S29=0,0,IF(O29<>"",(S29-(T29))/S29,V28)) -> 0.044444444 | W29: 26 | X29: =+IF((VLOOKUP(A29,List!B:C,2,0)-VLOOKUP(Summary!$P$7,List!B:C,2,0))=0,1,"") | Y29: =+IF((VLOOKUP(A29,List!B:C,2,0)-VLOOKUP(Summary!$P$7,List!B:C,2,0))>=0,1,"") -> 1 | Z29: =+IF((VLOOKUP(A29,List!B:C,2,0)-VLOOKUP(Summary!$P$7,List!B:C,2,0))>0,1,"") -> 1 | AA29: =+IFERROR(IF(Z29="","",IF(YEAR(G29)>C29,1,IF(YEAR(G29)=C29,IF(MONTH(G29)>=B29,1,2)))),2) -> 2 | AB29: =+IF(AA29="","",IF(Summary!$J$7="Fixed Price","",IF(M29="",IF(I29="","",1),""))) | AC29: =+IFERROR(I29*AA29,0) -> 0 | AD29: =+IF(AA29="",+IF(N29>#REF!,#REF!,IF(N29>#REF!,#REF!,IF(N29>#REF!,#REF!,IF(N29>#REF!,#REF!,IF(N29>#REF!,#REF!,IF(N29>#REF!,#REF!,IF(N29>#REF!,#REF!,IF(N29>#REF!,#REF!,#REF!)))))))),0) -> 0
A30: =CONCATENATE(C30,"-",B30) -> - | B30: =IF(W30<=$W$2,IF(B29>11,1,B29+1),"") | C30: =IF(W30<=$W$2,IF(B29>11,C29+1,C29),"") | D30: =CONCATENATE(C30,"-",B30) -> - | E30: =+IF($B30="","",Summary!$P$4) | F30: =+IF($B30="","",Summary!$P$5) | G30: =+IF($B30="","",Summary!$P$6) | H30: =+IF($B30="","",IF(U30<-15%,"Red",IF(U30<0%,"Amber","Green"))) | N30: =O30 -> 0 | O30: 0 | P30: =I30+P29 -> 208680.78 | Q30: =Q29+J30 -> 283.25 | R30: =K30+R29 -> 52.49 | S30: =N30+S29 -> 90 | T30: =O30+T29 -> 86 | U30: =IF(Q30=0,0,IF(K30<>"",(Q30-(R30+L30))/Q30,U29)) -> 0.29306397 | V30: =IF(S30=0,0,IF(O30<>"",(S30-(T30))/S30,V29)) -> 0.044444444 | W30: 27 | X30: =+IF((VLOOKUP(A30,List!B:C,2,0)-VLOOKUP(Summary!$P$7,List!B:C,2,0))=0,1,"") | Y30: =+IF((VLOOKUP(A30,List!B:C,2,0)-VLOOKUP(Summary!$P$7,List!B:C,2,0))>=0,1,"") -> 1 | Z30: =+IF((VLOOKUP(A30,List!B:C,2,0)-VLOOKUP(Summary!$P$7,List!B:C,2,0))>0,1,"") -> 1 | AA30: =+IFERROR(IF(Z30="","",IF(YEAR(G30)>C30,1,IF(YEAR(G30)=C30,IF(MONTH(G30)>=B30,1,2)))),2) -> 2 | AB30: =+IF(AA30="","",IF(Summary!$J$7="Fixed Price","",IF(M30="",IF(I30="","",1),""))) | AC30: =+IFERROR(I30*AA30,0) -> 0 | AD30: =+IF(AA30="",+IF(N30>#REF!,#REF!,IF(N30>#REF!,#REF!,IF(N30>#REF!,#REF!,IF(N30>#REF!,#REF!,IF(N30>#REF!,#REF!,IF(N30>#REF!,#REF!,IF(N30>#REF!,#REF!,IF(N30>#REF!,#REF!,#REF!)))))))),0) -> 0
A31: =CONCATENATE(C31,"-",B31) -> - | B31: =IF(W31<=$W$2,IF(B30>11,1,B30+1),"") | C31: =IF(W31<=$W$2,IF(B30>11,C30+1,C30),"") | D31: =CONCATENATE(C31,"-",B31) -> - | E31: =+IF($B31="","",Summary!$P$4) | F31: =+IF($B31="","",Summary!$P$5) | G31: =+IF($B31="","",Summary!$P$6) | H31: =+IF($B31="","",IF(U31<-15%,"Red",IF(U31<0%,"Amber","Green"))) | N31: =O31 -> 0 | O31: 0 | P31: =I31+P30 -> 208680.78 | Q31: =Q30+J31 -> 283.25 | R31: =K31+R30 -> 52.49 | S31: =N31+S30 -> 90 | T31: =O31+T30 -> 86 | U31: =IF(Q31=0,0,IF(K31<>"",(Q31-(R31+L31))/Q31,U30)) -> 0.29306397 | V31: =IF(S31=0,0,IF(O31<>"",(S31-(T31))/S31,V30)) -> 0.044444444 | W31: 28 | X31: =+IF((VLOOKUP(A31,List!B:C,2,0)-VLOOKUP(Summary!$P$7,List!B:C,2,0))=0,1,"") | Y31: =+IF((VLOOKUP(A31,List!B:C,2,0)-VLOOKUP(Summary!$P$7,List!B:C,2,0))>=0,1,"") -> 1 | Z31: =+IF((VLOOKUP(A31,List!B:C,2,0)-VLOOKUP(Summary!$P$7,List!B:C,2,0))>0,1,"") -> 1 | AA31: =+IFERROR(IF(Z31="","",IF(YEAR(G31)>C31,1,IF(YEAR(G31)=C31,IF(MONTH(G31)>=B31,1,2)))),2) -> 2 | AB31: =+IF(AA31="","",IF(Summary!$J$7="Fixed Price","",IF(M31="",IF(I31="","",1),""))) | AC31: =+IFERROR(I31*AA31,0) -> 0 | AD31: =+IF(AA31="",+IF(N31>#REF!,#REF!,IF(N31>#REF!,#REF!,IF(N31>#REF!,#REF!,IF(N31>#REF!,#REF!,IF(N31>#REF!,#REF!,IF(N31>#REF!,#REF!,IF(N31>#REF!,#REF!,IF(N31>#REF!,#REF!,#REF!)))))))),0) -> 0
A32: =CONCATENATE(C32,"-",B32) -> - | B32: =IF(W32<=$W$2,IF(B31>11,1,B31+1),"") | C32: =IF(W32<=$W$2,IF(B31>11,C31+1,C31),"") | D32: =CONCATENATE(C32,"-",B32) -> - | E32: =+IF($B32="","",Summary!$P$4) | F32: =+IF($B32="","",Summary!$P$5) | G32: =+IF($B32="","",Summary!$P$6) | H32: =+IF($B32="","",IF(U32<-15%,"Red",IF(U32<0%,"Amber","Green"))) | N32: =O32 -> 0 | O32: 0 | P32: =I32+P31 -> 208680.78 | Q32: =Q31+J32 -> 283.25 | R32: =K32+R31 -> 52.49 | S32: =N32+S31 -> 90 | T32: =O32+T31 -> 86 | U32: =IF(Q32=0,0,IF(K32<>"",(Q32-(R32+L32))/Q32,U31)) -> 0.29306397 | V32: =IF(S32=0,0,IF(O32<>"",(S32-(T32))/S32,V31)) -> 0.044444444 | W32: 29 | X32: =+IF((VLOOKUP(A32,List!B:C,2,0)-VLOOKUP(Summary!$P$7,List!B:C,2,0))=0,1,"") | Y32: =+IF((VLOOKUP(A32,List!B:C,2,0)-VLOOKUP(Summary!$P$7,List!B:C,2,0))>=0,1,"") -> 1 | Z32: =+IF((VLOOKUP(A32,List!B:C,2,0)-VLOOKUP(Summary!$P$7,List!B:C,2,0))>0,1,"") -> 1 | AA32: =+IFERROR(IF(Z32="","",IF(YEAR(G32)>C32,1,IF(YEAR(G32)=C32,IF(MONTH(G32)>=B32,1,2)))),2) -> 2 | AB32: =+IF(AA32="","",IF(Summary!$J$7="Fixed Price","",IF(M32="",IF(I32="","",1),""))) | AC32: =+IFERROR(I32*AA32,0) -> 0
A33: =CONCATENATE(C33,"-",B33) -> - | B33: =IF(W33<=$W$2,IF(B32>11,1,B32+1),"") | C33: =IF(W33<=$W$2,IF(B32>11,C32+1,C32),"") | D33: =CONCATENATE(C33,"-",B33) -> - | E33: =+IF($B33="","",Summary!$P$4) | F33: =+IF($B33="","",Summary!$P$5) | G33: =+IF($B33="","",Summary!$P$6) | H33: =+IF($B33="","",IF(U33<-15%,"Red",IF(U33<0%,"Amber","Green"))) | N33: =O33 -> 0 | O33: 0 | P33: =I33+P32 -> 208680.78 | Q33: =Q32+J33 -> 283.25 | R33: =K33+R32 -> 52.49 | S33: =N33+S32 -> 90 | T33: =O33+T32 -> 86 | U33: =IF(Q33=0,0,IF(K33<>"",(Q33-(R33+L33))/Q33,U32)) -> 0.29306397 | V33: =IF(S33=0,0,IF(O33<>"",(S33-(T33))/S33,V32)) -> 0.044444444 | W33: 30 | X33: =+IF((VLOOKUP(A33,List!B:C,2,0)-VLOOKUP(Summary!$P$7,List!B:C,2,0))=0,1,"") | Y33: =+IF((VLOOKUP(A33,List!B:C,2,0)-VLOOKUP(Summary!$P$7,List!B:C,2,0))>=0,1,"") -> 1 | Z33: =+IF((VLOOKUP(A33,List!B:C,2,0)-VLOOKUP(Summary!$P$7,List!B:C,2,0))>0,1,"") -> 1 | AA33: =+IFERROR(IF(Z33="","",IF(YEAR(G33)>C33,1,IF(YEAR(G33)=C33,IF(MONTH(G33)>=B33,1,2)))),2) -> 2 | AB33: =+IF(AA33="","",IF(Summary!$J$7="Fixed Price","",IF(M33="",IF(I33="","",1),""))) | AC33: =+IFERROR(I33*AA33,0) -> 0
A34: =CONCATENATE(C34,"-",B34) -> - | B34: =IF(W34<=$W$2,IF(B33>11,1,B33+1),"") | C34: =IF(W34<=$W$2,IF(B33>11,C33+1,C33),"") | D34: =CONCATENATE(C34,"-",B34) -> - | E34: =+IF($B34="","",Summary!$P$4) | F34: =+IF($B34="","",Summary!$P$5) | G34: =+IF($B34="","",Summary!$P$6) | H34: =+IF($B34="","",IF(U34<-15%,"Red",IF(U34<0%,"Amber","Green"))) | N34: =O34 -> 0 | O34: 0 | P34: =I34+P33 -> 208680.78 | Q34: =Q33+J34 -> 283.25 | R34: =K34+R33 -> 52.49 | S34: =N34+S33 -> 90 | T34: =O34+T33 -> 86 | U34: =IF(Q34=0,0,IF(K34<>"",(Q34-(R34+L34))/Q34,U33)) -> 0.29306397 | V34: =IF(S34=0,0,IF(O34<>"",(S34-(T34))/S34,V33)) -> 0.044444444 | W34: 31 | X34: =+IF((VLOOKUP(A34,List!B:C,2,0)-VLOOKUP(Summary!$P$7,List!B:C,2,0))=0,1,"") | Y34: =+IF((VLOOKUP(A34,List!B:C,2,0)-VLOOKUP(Summary!$P$7,List!B:C,2,0))>=0,1,"") -> 1 | Z34: =+IF((VLOOKUP(A34,List!B:C,2,0)-VLOOKUP(Summary!$P$7,List!B:C,2,0))>0,1,"") -> 1 | AA34: =+IFERROR(IF(Z34="","",IF(YEAR(G34)>C34,1,IF(YEAR(G34)=C34,IF(MONTH(G34)>=B34,1,2)))),2) -> 2 | AB34: =+IF(AA34="","",IF(Summary!$J$7="Fixed Price","",IF(M34="",IF(I34="","",1),""))) | AC34: =+IFERROR(I34*AA34,0) -> 0
A35: =CONCATENATE(C35,"-",B35) -> - | B35: =IF(W35<=$W$2,IF(B34>11,1,B34+1),"") | C35: =IF(W35<=$W$2,IF(B34>11,C34+1,C34),"") | D35: =CONCATENATE(C35,"-",B35) -> - | E35: =+IF($B35="","",Summary!$P$4) | F35: =+IF($B35="","",Summary!$P$5) | G35: =+IF($B35="","",Summary!$P$6) | H35: =+IF($B35="","",IF(U35<-15%,"Red",IF(U35<0%,"Amber","Green"))) | N35: =O35 -> 0 | O35: 0 | P35: =I35+P34 -> 208680.78 | Q35: =Q34+J35 -> 283.25 | R35: =K35+R34 -> 52.49 | S35: =N35+S34 -> 90 | T35: =O35+T34 -> 86 | U35: =IF(Q35=0,0,IF(K35<>"",(Q35-(R35+L35))/Q35,U34)) -> 0.29306397 | V35: =IF(S35=0,0,IF(O35<>"",(S35-(T35))/S35,V34)) -> 0.044444444 | W35: 32 | X35: =+IF((VLOOKUP(A35,List!B:C,2,0)-VLOOKUP(Summary!$P$7,List!B:C,2,0))=0,1,"") | Y35: =+IF((VLOOKUP(A35,List!B:C,2,0)-VLOOKUP(Summary!$P$7,List!B:C,2,0))>=0,1,"") -> 1 | Z35: =+IF((VLOOKUP(A35,List!B:C,2,0)-VLOOKUP(Summary!$P$7,List!B:C,2,0))>0,1,"") -> 1 | AA35: =+IFERROR(IF(Z35="","",IF(YEAR(G35)>C35,1,IF(YEAR(G35)=C35,IF(MONTH(G35)>=B35,1,2)))),2) -> 2 | AB35: =+IF(AA35="","",IF(Summary!$J$7="Fixed Price","",IF(M35="",IF(I35="","",1),""))) | AC35: =+IFERROR(I35*AA35,0) -> 0
A36: =CONCATENATE(C36,"-",B36) -> - | B36: =IF(W36<=$W$2,IF(B35>11,1,B35+1),"") | C36: =IF(W36<=$W$2,IF(B35>11,C35+1,C35),"") | D36: =CONCATENATE(C36,"-",B36) -> - | E36: =+IF($B36="","",Summary!$P$4) | F36: =+IF($B36="","",Summary!$P$5) | G36: =+IF($B36="","",Summary!$P$6) | H36: =+IF($B36="","",IF(U36<-15%,"Red",IF(U36<0%,"Amber","Green"))) | N36: =O36 -> 0 | O36: 0 | P36: =I36+P35 -> 208680.78 | Q36: =Q35+J36 -> 283.25 | R36: =K36+R35 -> 52.49 | S36: =N36+S35 -> 90 | T36: =O36+T35 -> 86 | U36: =IF(Q36=0,0,IF(K36<>"",(Q36-(R36+L36))/Q36,U35)) -> 0.29306397 | V36: =IF(S36=0,0,IF(O36<>"",(S36-(T36))/S36,V35)) -> 0.044444444 | W36: 33 | X36: =+IF((VLOOKUP(A36,List!B:C,2,0)-VLOOKUP(Summary!$P$7,List!B:C,2,0))=0,1,"") | Y36: =+IF((VLOOKUP(A36,List!B:C,2,0)-VLOOKUP(Summary!$P$7,List!B:C,2,0))>=0,1,"") -> 1 | Z36: =+IF((VLOOKUP(A36,List!B:C,2,0)-VLOOKUP(Summary!$P$7,List!B:C,2,0))>0,1,"") -> 1 | AA36: =+IFERROR(IF(Z36="","",IF(YEAR(G36)>C36,1,IF(YEAR(G36)=C36,IF(MONTH(G36)>=B36,1,2)))),2) -> 2 | AB36: =+IF(AA36="","",IF(Summary!$J$7="Fixed Price","",IF(M36="",IF(I36="","",1),""))) | AC36: =+IFERROR(I36*AA36,0) -> 0
A37: =CONCATENATE(C37,"-",B37) -> - | B37: =IF(W37<=$W$2,IF(B36>11,1,B36+1),"") | C37: =IF(W37<=$W$2,IF(B36>11,C36+1,C36),"") | D37: =CONCATENATE(C37,"-",B37) -> - | E37: =+IF($B37="","",Summary!$P$4) | F37: =+IF($B37="","",Summary!$P$5) | G37: =+IF($B37="","",Summary!$P$6) | H37: =+IF($B37="","",IF(U37<-15%,"Red",IF(U37<0%,"Amber","Green"))) | N37: =O37 -> 0 | O37: 0 | P37: =I37+P36 -> 208680.78 | Q37: =Q36+J37 -> 283.25 | R37: =K37+R36 -> 52.49 | S37: =N37+S36 -> 90 | T37: =O37+T36 -> 86 | U37: =IF(Q37=0,0,IF(K37<>"",(Q37-(R37+L37))/Q37,U36)) -> 0.29306397 | V37: =IF(S37=0,0,IF(O37<>"",(S37-(T37))/S37,V36)) -> 0.044444444 | W37: 34 | X37: =+IF((VLOOKUP(A37,List!B:C,2,0)-VLOOKUP(Summary!$P$7,List!B:C,2,0))=0,1,"") | Y37: =+IF((VLOOKUP(A37,List!B:C,2,0)-VLOOKUP(Summary!$P$7,List!B:C,2,0))>=0,1,"") -> 1 | Z37: =+IF((VLOOKUP(A37,List!B:C,2,0)-VLOOKUP(Summary!$P$7,List!B:C,2,0))>0,1,"") -> 1 | AA37: =+IFERROR(IF(Z37="","",IF(YEAR(G37)>C37,1,IF(YEAR(G37)=C37,IF(MONTH(G37)>=B37,1,2)))),2) -> 2 | AB37: =+IF(AA37="","",IF(Summary!$J$7="Fixed Price","",IF(M37="",IF(I37="","",1),""))) | AC37: =+IFERROR(I37*AA37,0) -> 0
A38: =CONCATENATE(C38,"-",B38) -> - | B38: =IF(W38<=$W$2,IF(B37>11,1,B37+1),"") | C38: =IF(W38<=$W$2,IF(B37>11,C37+1,C37),"") | D38: =CONCATENATE(C38,"-",B38) -> - | E38: =+IF($B38="","",Summary!$P$4) | F38: =+IF($B38="","",Summary!$P$5) | G38: =+IF($B38="","",Summary!$P$6) | H38: =+IF($B38="","",IF(U38<-15%,"Red",IF(U38<0%,"Amber","Green"))) | N38: =O38 -> 0 | O38: 0 | P38: =I38+P37 -> 208680.78 | Q38: =Q37+J38 -> 283.25 | R38: =K38+R37 -> 52.49 | S38: =N38+S37 -> 90 | T38: =O38+T37 -> 86 | U38: =IF(Q38=0,0,IF(K38<>"",(Q38-(R38+L38))/Q38,U37)) -> 0.29306397 | V38: =IF(S38=0,0,IF(O38<>"",(S38-(T38))/S38,V37)) -> 0.044444444 | W38: 35 | X38: =+IF((VLOOKUP(A38,List!B:C,2,0)-VLOOKUP(Summary!$P$7,List!B:C,2,0))=0,1,"") | Y38: =+IF((VLOOKUP(A38,List!B:C,2,0)-VLOOKUP(Summary!$P$7,List!B:C,2,0))>=0,1,"") -> 1 | Z38: =+IF((VLOOKUP(A38,List!B:C,2,0)-VLOOKUP(Summary!$P$7,List!B:C,2,0))>0,1,"") -> 1 | AA38: =+IFERROR(IF(Z38="","",IF(YEAR(G38)>C38,1,IF(YEAR(G38)=C38,IF(MONTH(G38)>=B38,1,2)))),2) -> 2 | AB38: =+IF(AA38="","",IF(Summary!$J$7="Fixed Price","",IF(M38="",IF(I38="","",1),""))) | AC38: =+IFERROR(I38*AA38,0) -> 0
A39: =CONCATENATE(C39,"-",B39) -> - | B39: =IF(W39<=$W$2,IF(B38>11,1,B38+1),"") | C39: =IF(W39<=$W$2,IF(B38>11,C38+1,C38),"") | D39: =CONCATENATE(C39,"-",B39) -> - | E39: =+IF($B39="","",Summary!$P$4) | F39: =+IF($B39="","",Summary!$P$5) | G39: =+IF($B39="","",Summary!$P$6) | H39: =+IF($B39="","",IF(U39<-15%,"Red",IF(U39<0%,"Amber","Green"))) | N39: =O39 -> 0 | O39: 0 | P39: =I39+P38 -> 208680.78 | Q39: =Q38+J39 -> 283.25 | R39: =K39+R38 -> 52.49 | S39: =N39+S38 -> 90 | T39: =O39+T38 -> 86 | U39: =IF(Q39=0,0,IF(K39<>"",(Q39-(R39+L39))/Q39,U38)) -> 0.29306397 | V39: =IF(S39=0,0,IF(O39<>"",(S39-(T39))/S39,V38)) -> 0.044444444 | W39: 36 | X39: =+IF((VLOOKUP(A39,List!B:C,2,0)-VLOOKUP(Summary!$P$7,List!B:C,2,0))=0,1,"") | Y39: =+IF((VLOOKUP(A39,List!B:C,2,0)-VLOOKUP(Summary!$P$7,List!B:C,2,0))>=0,1,"") -> 1 | Z39: =+IF((VLOOKUP(A39,List!B:C,2,0)-VLOOKUP(Summary!$P$7,List!B:C,2,0))>0,1,"") -> 1 | AA39: =+IFERROR(IF(Z39="","",IF(YEAR(G39)>C39,1,IF(YEAR(G39)=C39,IF(MONTH(G39)>=B39,1,2)))),2) -> 2 | AB39: =+IF(AA39="","",IF(Summary!$J$7="Fixed Price","",IF(M39="",IF(I39="","",1),""))) | AC39: =+IFERROR(I39*AA39,0) -> 0
A40: =CONCATENATE(C40,"-",B40) -> - | B40: =IF(W40<=$W$2,IF(B39>11,1,B39+1),"") | C40: =IF(W40<=$W$2,IF(B39>11,C39+1,C39),"") | D40: =CONCATENATE(C40,"-",B40) -> - | E40: =+IF($B40="","",Summary!$P$4) | F40: =+IF($B40="","",Summary!$P$5) | G40: =+IF($B40="","",Summary!$P$6) | H40: =+IF($B40="","",IF(U40<-15%,"Red",IF(U40<0%,"Amber","Green"))) | N40: =O40 -> 0 | O40: 0 | P40: =I40+P39 -> 208680.78 | Q40: =Q39+J40 -> 283.25 | R40: =K40+R39 -> 52.49 | S40: =N40+S39 -> 90 | T40: =O40+T39 -> 86 | U40: =IF(Q40=0,0,IF(K40<>"",(Q40-(R40+L40))/Q40,U39)) -> 0.29306397 | V40: =IF(S40=0,0,IF(O40<>"",(S40-(T40))/S40,V39)) -> 0.044444444 | W40: 37 | X40: =+IF((VLOOKUP(A40,List!B:C,2,0)-VLOOKUP(Summary!$P$7,List!B:C,2,0))=0,1,"") | Y40: =+IF((VLOOKUP(A40,List!B:C,2,0)-VLOOKUP(Summary!$P$7,List!B:C,2,0))>=0,1,"") -> 1 | Z40: =+IF((VLOOKUP(A40,List!B:C,2,0)-VLOOKUP(Summary!$P$7,List!B:C,2,0))>0,1,"") -> 1 | AA40: =+IFERROR(IF(Z40="","",IF(YEAR(G40)>C40,1,IF(YEAR(G40)=C40,IF(MONTH(G40)>=B40,1,2)))),2) -> 2 | AB40: =+IF(AA40="","",IF(Summary!$J$7="Fixed Price","",IF(M40="",IF(I40="","",1),""))) | AC40: =+IFERROR(I40*AA40,0) -> 0
A41: =CONCATENATE(C41,"-",B41) -> - | B41: =IF(W41<=$W$2,IF(B40>11,1,B40+1),"") | C41: =IF(W41<=$W$2,IF(B40>11,C40+1,C40),"") | D41: =CONCATENATE(C41,"-",B41) -> - | E41: =+IF($B41="","",Summary!$P$4) | F41: =+IF($B41="","",Summary!$P$5) | G41: =+IF($B41="","",Summary!$P$6) | H41: =+IF($B41="","",IF(U41<-15%,"Red",IF(U41<0%,"Amber","Green"))) | N41: =O41 -> 0 | O41: 0 | P41: =I41+P40 -> 208680.78 | Q41: =Q40+J41 -> 283.25 | R41: =K41+R40 -> 52.49 | S41: =N41+S40 -> 90 | T41: =O41+T40 -> 86 | U41: =IF(Q41=0,0,IF(K41<>"",(Q41-(R41+L41))/Q41,U40)) -> 0.29306397 | V41: =IF(S41=0,0,IF(O41<>"",(S41-(T41))/S41,V40)) -> 0.044444444 | W41: 38 | X41: =+IF((VLOOKUP(A41,List!B:C,2,0)-VLOOKUP(Summary!$P$7,List!B:C,2,0))=0,1,"") | Y41: =+IF((VLOOKUP(A41,List!B:C,2,0)-VLOOKUP(Summary!$P$7,List!B:C,2,0))>=0,1,"") -> 1 | Z41: =+IF((VLOOKUP(A41,List!B:C,2,0)-VLOOKUP(Summary!$P$7,List!B:C,2,0))>0,1,"") -> 1 | AA41: =+IFERROR(IF(Z41="","",IF(YEAR(G41)>C41,1,IF(YEAR(G41)=C41,IF(MONTH(G41)>=B41,1,2)))),2) -> 2 | AB41: =+IF(AA41="","",IF(Summary!$J$7="Fixed Price","",IF(M41="",IF(I41="","",1),""))) | AC41: =+IFERROR(I41*AA41,0) -> 0
A42: =CONCATENATE(C42,"-",B42) -> - | B42: =IF(W42<=$W$2,IF(B41>11,1,B41+1),"") | C42: =IF(W42<=$W$2,IF(B41>11,C41+1,C41),"") | D42: =CONCATENATE(C42,"-",B42) -> - | E42: =+IF($B42="","",Summary!$P$4) | F42: =+IF($B42="","",Summary!$P$5) | G42: =+IF($B42="","",Summary!$P$6) | H42: =+IF($B42="","",IF(U42<-15%,"Red",IF(U42<0%,"Amber","Green"))) | N42: =O42 -> 0 | O42: 0 | P42: =I42+P41 -> 208680.78 | Q42: =Q41+J42 -> 283.25 | R42: =K42+R41 -> 52.49 | S42: =N42+S41 -> 90 | T42: =O42+T41 -> 86 | U42: =IF(Q42=0,0,IF(K42<>"",(Q42-(R42+L42))/Q42,U41)) -> 0.29306397 | V42: =IF(S42=0,0,IF(O42<>"",(S42-(T42))/S42,V41)) -> 0.044444444 | W42: 39 | X42: =+IF((VLOOKUP(A42,List!B:C,2,0)-VLOOKUP(Summary!$P$7,List!B:C,2,0))=0,1,"") | Y42: =+IF((VLOOKUP(A42,List!B:C,2,0)-VLOOKUP(Summary!$P$7,List!B:C,2,0))>=0,1,"") -> 1 | Z42: =+IF((VLOOKUP(A42,List!B:C,2,0)-VLOOKUP(Summary!$P$7,List!B:C,2,0))>0,1,"") -> 1 | AA42: =+IFERROR(IF(Z42="","",IF(YEAR(G42)>C42,1,IF(YEAR(G42)=C42,IF(MONTH(G42)>=B42,1,2)))),2) -> 2 | AB42: =+IF(AA42="","",IF(Summary!$J$7="Fixed Price","",IF(M42="",IF(I42="","",1),""))) | AC42: =+IFERROR(I42*AA42,0) -> 0
A43: =CONCATENATE(C43,"-",B43) -> - | B43: =IF(W43<=$W$2,IF(B42>11,1,B42+1),"") | C43: =IF(W43<=$W$2,IF(B42>11,C42+1,C42),"") | D43: =CONCATENATE(C43,"-",B43) -> - | E43: =+IF($B43="","",Summary!$P$4) | F43: =+IF($B43="","",Summary!$P$5) | G43: =+IF($B43="","",Summary!$P$6) | H43: =+IF($B43="","",IF(U43<-15%,"Red",IF(U43<0%,"Amber","Green"))) | N43: =O43 -> 0 | O43: 0 | P43: =I43+P42 -> 208680.78 | Q43: =Q42+J43 -> 283.25 | R43: =K43+R42 -> 52.49 | S43: =N43+S42 -> 90 | T43: =O43+T42 -> 86 | U43: =IF(Q43=0,0,IF(K43<>"",(Q43-(R43+L43))/Q43,U42)) -> 0.29306397 | V43: =IF(S43=0,0,IF(O43<>"",(S43-(T43))/S43,V42)) -> 0.044444444 | W43: 40 | X43: =+IF((VLOOKUP(A43,List!B:C,2,0)-VLOOKUP(Summary!$P$7,List!B:C,2,0))=0,1,"") | Y43: =+IF((VLOOKUP(A43,List!B:C,2,0)-VLOOKUP(Summary!$P$7,List!B:C,2,0))>=0,1,"") -> 1 | Z43: =+IF((VLOOKUP(A43,List!B:C,2,0)-VLOOKUP(Summary!$P$7,List!B:C,2,0))>0,1,"") -> 1 | AA43: =+IFERROR(IF(Z43="","",IF(YEAR(G43)>C43,1,IF(YEAR(G43)=C43,IF(MONTH(G43)>=B43,1,2)))),2) -> 2 | AB43: =+IF(AA43="","",IF(Summary!$J$7="Fixed Price","",IF(M43="",IF(I43="","",1),""))) | AC43: =+IFERROR(I43*AA43,0) -> 0
... A63: =CONCATENATE(C63,"-",B63) -> - | B63: =IF(W63<=$W$2,IF(B62>11,1,B62+1),"") | C63: =IF(W63<=$W$2,IF(B62>11,C62+1,C62),"") | D63: =CONCATENATE(C63,"-",B63) -> - | E63: =+IF($B63="","",Summary!$P$4) | F63: =+IF($B63="","",Summary!$P$5) | G63: =+IF($B63="","",Summary!$P$6) | H63: =+IF($B63="","",IF(U63<-15%,"Red",IF(U63<0%,"Amber","Green"))) | N63: =O63 -> 0 | O63: 0 | P63: =I63+P62 -> 208680.78 | Q63: =Q62+J63 -> 283.25 | R63: =K63+R62 -> 52.49 | S63: =N63+S62 -> 90 | T63: =O63+T62 -> 86 | U63: =IF(Q63=0,0,IF(K63<>"",(Q63-(R63+L63))/Q63,U62)) -> 0.29306397 | V63: =IF(S63=0,0,IF(O63<>"",(S63-(T63))/S63,V62)) -> 0.044444444 | W63: 48 | X63: =+IF((VLOOKUP(A63,List!B:C,2,0)-VLOOKUP(Summary!$P$7,List!B:C,2,0))=0,1,"") | Y63: =+IF((VLOOKUP(A63,List!B:C,2,0)-VLOOKUP(Summary!$P$7,List!B:C,2,0))>=0,1,"") -> 1 | Z63: =+IF((VLOOKUP(A63,List!B:C,2,0)-VLOOKUP(Summary!$P$7,List!B:C,2,0))>0,1,"") -> 1 | AA63: =+IFERROR(IF(Z63="","",IF(YEAR(G63)>C63,1,IF(YEAR(G63)=C63,IF(MONTH(G63)>=B63,1,2)))),2) -> 2 | AB63: =+IF(AA63="","",IF(Summary!$J$7="Fixed Price","",IF(M63="",IF(I63="","",1),""))) | AC63: =+IFERROR(I63*AA63,0) -> 0

Sheet CN
C1: CN Financials | W1: Number of lines | X1: Period of the month reported | Y1: Period after month reported including | Z1: Period after month reported excluding | AA1: Period after month reported until end date | AB1: Sell Value if T&M | AC1: Sell value future | AD1: Sell value past
W2: =(YEAR(Summary!P6)-YEAR(Summary!P4))*12+MONTH(Summary!P6)-MONTH(Summary!P4)+1 -> 25
A3: Select Report Month | B3: Month | C3: Year | D3: Year-Month | E3: Start Date | F3: Plan End Date | G3: Estimate End Date | H3: Status | I3: Sell Value | J3: Effort | K3: Timesheet | L3: OTS (Snapshot) | M3: Allocations | N3: Plan Tickets | O3: Real Tickets | P3: Total Sell Value | Q3: Total Sell Effort | R3: Total Spent Effort | S3: Total Sell Tickets | T3: Total Real Tickets | U3: % Deviation | V3: % Ticket Deviation | W3: # ID
A4: =CONCATENATE(C4,"-",B4) -> 2025-9 | B4: =MONTH(Summary!P4) -> 9 | C4: =YEAR(Summary!P4) -> 2025 | D4: =CONCATENATE(C4,"-",B4) -> 2025-9 | E4: =+IF($B4="","",Summary!$P$4) -> 45929 | F4: =+IF($B4="","",Summary!$P$5) -> 46657 | G4: =+IF($B4="","",Summary!$P$6) -> 46657 | H4: =+IF($B4="","",IF(U4<-15%,"Red",IF(U4<0%,"Amber","Green"))) -> Green | N4: =O4 -> #REF! | O4: =COUNTIFS(#REF!,">="&DATE($C4,$B4,1),#REF!,"<="&EOMONTH(DATE($C4,$B4,1),0),#REF!,"Incident")+ COUNTIFS(#REF!,">="&DATE($C4,$B4,1),#REF!,"<="&EOMONTH(DATE($C4,$B4,1),0),#REF!,"user_request") -> #REF! | P4: =I4 -> 0 | Q4: =J4 -> 0 | R4: =K4 -> 0 | S4: =N4 -> #REF! | T4: =O4 -> #REF! | U4: =IF(Q4=0,0,IF(K4<>"",(Q4-(R4+L4))/Q4,U3)) -> 0 | V4: =IF(S4=0,0,IF(O4<>"",(S4-(T4))/S4,V3)) -> #REF! | W4: 1 | X4: =+IF((VLOOKUP(A4,List!B:C,2,0)-VLOOKUP(Summary!$P$7,List!B:C,2,0))=0,1,"") | Y4: =+IF((VLOOKUP(A4,List!B:C,2,0)-VLOOKUP(Summary!$P$7,List!B:C,2,0))>=0,1,"") | Z4: =+IF((VLOOKUP(A4,List!B:C,2,0)-VLOOKUP(Summary!$P$7,List!B:C,2,0))>0,1,"") | AA4: =+IFERROR(IF(Z4="","",IF(YEAR(G4)>C4,1,IF(YEAR(G4)=C4,IF(MONTH(G4)>=B4,1,2)))),2) | AB4: =+IF(AA4="","",IF(Summary!$J$7="Fixed Price","",IF(M4="",IF(I4="","",1),""))) | AC4: =+IFERROR(I4*AA4,0) -> 0 | AD4: =+IF(AA4="",+IF(N4>#REF!,#REF!,IF(N4>#REF!,#REF!,IF(N4>#REF!,#REF!,IF(N4>#REF!,#REF!,IF(N4>#REF!,#REF!,IF(N4>#REF!,#REF!,IF(N4>#REF!,#REF!,IF(N4>#REF!,#REF!,#REF!)))))))),0) -> #REF!
